Workbook

Sheet フォームの回答 1
A1: タイムスタンプ | B1: 無題の質問

Sheet 支払い回答
A1: タイムスタンプ | B1: メールアドレス | C1: どの決済方法での支払いになりますか？ | D1: どの支出項目に計上される支払いですか？ | E1: 金額はいくらですか？（短文記述） | F1: 何を買いましたか？or何に使いましたか？（長文） | G1: いまどんな気持ちですか？(チェックボックス) | H1: いまどんな気持ちですか？(プルダウン) | I1: いまどんな気持ちですか？(均等目盛) | J1: いまの気分は？(評価) | K1: いまの気分は？(グリッド選択式) [第一象限] | L1: いまの気分は？(チェックボックスグリッド) [合理的（金銭的）] | M1: 今日の日付は？ | N1: 今の時刻は？ | O1: ★入力済み
A2: 45903.697 | B2: lycourgos.yoshioka@gmail.com | C2: oliveカード支払い | D2: 昼飯 | E2: 夏季休暇 | F2: 夏季休暇めっちゃありがたい | G2: 最高, 普通 | H2: 最高 | I2: 7 | J2: 6 | K2: 第二象限 | L2: 体調（良い） | M2: 45903 | N2: 0.69652778 | O2: TRUE
A3: 45909.355 | B3: lycourgos.yoshioka@gmail.com | C3: PayPayカード支払い | D3: 物品購入費 | E3: 3,300円 | F3: 仕事頑張ろう | G3: 最高, 普通 | H3: 最高 | I3: 5 | J3: 4 | M3: 45910 | N3: 0.35486111 | O3: TRUE
A4: 45909.361 | B4: lycourgos.yoshioka@gmail.com | C4: メルペイ | D4: スーパー | E4: 560 | F4: お茶4本 | G4: 最高 | H4: 最高 | I4: 5 | J4: 5 | O4: TRUE
A5: 45922.87 | B5: lycourgos.yoshioka@gmail.com | C5: PayPay残高支払い | D5: 夜飯 | E5: 181 | F5: サラダチキンバー | G5: 普通 | H5: 普通 | I5: 4 | J5: 4 | O5: TRUE
O6: FALSE
O7: FALSE
O8: FALSE
O9: FALSE
O10: FALSE
O11: FALSE
O12: FALSE
O13: FALSE
O14: FALSE
O15: FALSE
O16: FALSE
O17: FALSE
... O125: FALSE

Sheet サマリ
B2: 30歳までの目標 | M2: 2026年度にやりたいこと
B4: テーマ | D4: 映画やドラマのようなストーリー | M4: 稼ぎ | O4: 年収1,000万を稼ぐ経験をする（2026年1月～2026年12月）
B6: 夢 | D6: 好きな人と生きていく（自分も主役となり友達と事業をして生きていきたい） | M6: 美容 | O6: 年間予算120万円を投下して外見磨きを行う（脱毛、眉毛サロン、歯科矯正、パーソナルジム）
B8: 目標 | D8: 30歳まで(2028年3月10日)に実際に事業継承か起業で勝てるビジネスを始める | M8: 旅行 | O8: 予算を決めて海外旅行に2回以上行く（バンコク&グアム＆ベトナム？）
B10: やること | D10: 生活習慣とお金を管理し資産1,000万円~3,000万円を固く作りに行く | M10: 読書・発信 | O10: 年間50冊の読書&noteの発信活動（毎日投稿）
B13: (FY-1収支) | G13: (FY-2収支) | L13: (FY-3収支) | Q13: (FY-4収支)
B14: 月 | C14: 支出 | D14: 収入 | E14: 収支 | G14: 月 | H14: 支出 | I14: 収入 | J14: 収支 | L14: 月 | M14: 支出 | N14: 収入 | O14: 収支 | Q14: 月 | R14: 支出 | S14: 収入 | T14: 収支
B15: 2024年5月 | C15: 201303 | D15: 304485 | E15: 103182 | G15: 2025年4月 | H15: ='FY-2(月次)支出'!D3 -> 328579 | I15: ='FY-2(月次)収入'!D3 -> 362756 | J15: =I15-H15 -> 34177 | L15: 2026年4月 | M15: ='FY-3(月次)支出 '!D3 -> 440344 | N15: ='FY-3(月次)収入'!D3 -> 575013.96 | O15: =N15-M15 -> 134669.96 | Q15: 2027年4月 | T15: =S15-R15 -> 0
B16: 2024年6月 | C16: 204637 | D16: 408757 | E16: 204120 | G16: 2025年5月 | H16: ='FY-2(月次)支出'!E3 -> 458043 | I16: ='FY-2(月次)収入'!E3 -> 280024 | J16: =I16-H16 -> -178019 | L16: 2026年5月 | M16: ='FY-3(月次)支出 '!E3 -> 447333 | N16: ='FY-3(月次)収入'!E3 -> 518059.08 | O16: =N16-M16 -> 70726.075 | Q16: 2027年5月 | T16: =S16-R16 -> 0
B17: 2024年7月 | C17: 206041 | D17: 339296 | E17: 133255 | G17: 2025年6月 | H17: ='FY-2(月次)支出'!F3 -> 320775 | I17: ='FY-2(月次)収入'!F3 -> 68896 | J17: =I17-H17 -> -251879 | L17: 2026年6月 | M17: ='FY-3(月次)支出 '!F3 -> 392616 | N17: ='FY-3(月次)収入'!F3 -> 549667.74 | O17: =N17-M17 -> 157051.74 | Q17: 2027年6月 | T17: =S17-R17 -> 0
B18: 2024年8月 | C18: 229626 | D18: 338764 | E18: 109138 | G18: 2025年7月 | H18: ='FY-2(月次)支出'!G3 -> 314993 | I18: ='FY-2(月次)収入'!G3 -> 473086 | J18: =I18-H18 -> 158093 | L18: 2026年7月 | M18: ='FY-3(月次)支出 '!G3 -> 494717 | N18: ='FY-3(月次)収入'!G3 -> 538747.85 | O18: =N18-M18 -> 44030.85 | Q18: 2027年7月 | T18: =S18-R18 -> 0
B19: 2024年9月 | C19: 210893 | D19: 318196 | E19: 107303 | G19: 2025年8月 | H19: ='FY-2(月次)支出'!H3 -> 335534 | I19: ='FY-2(月次)収入'!H3 -> 502474 | J19: =I19-H19 -> 166940 | L19: 2026年8月 | M19: ='FY-3(月次)支出 '!H3 -> 588753 | N19: ='FY-3(月次)収入'!H3 -> 745190.1 | O19: =N19-M19 -> 156437.1 | Q19: 2027年8月 | T19: =S19-R19 -> 0
B20: 2024年10月 | C20: 270707 | D20: 361408 | E20: 90701 | G20: 2025年9月 | H20: ='FY-2(月次)支出'!I3 -> 340477 | I20: ='FY-2(月次)収入'!I3 -> 584444 | J20: =I20-H20 -> 243967 | L20: 2026年9月 | M20: ='FY-3(月次)支出 '!I3 -> 849403 | N20: ='FY-3(月次)収入'!I3 -> 861996.07 | O20: =N20-M20 -> 12593.07 | Q20: 2027年9月 | T20: =S20-R20 -> 0
B21: 2024年11月 | C21: 281773 | D21: 360882 | E21: 79109 | G21: 2025年10月 | H21: ='FY-2(月次)支出'!J3 -> 514909 | I21: ='FY-2(月次)収入'!J3 -> 524857 | J21: =I21-H21 -> 9948 | L21: 2026年10月 | M21: ='FY-3(月次)支出 '!J3 -> 529403 | N21: ='FY-3(月次)収入'!J3 -> 757549.43 | O21: =N21-M21 -> 228146.43 | Q21: 2027年10月 | T21: =S21-R21 -> 0
B22: 2024年12月 | C22: 341879 | D22: 332786 | E22: -9093 | G22: 2025年11月 | H22: ='FY-2(月次)支出'!K3 -> 566502 | I22: ='FY-2(月次)収入'!K3 -> 584601.18 | J22: =I22-H22 -> 18099.183 | L22: 2026年11月 | M22: ='FY-3(月次)支出 '!K3 -> 529403 | N22: ='FY-3(月次)収入'!K3 -> 1161938.8 | O22: =N22-M22 -> 632535.77 | Q22: 2027年11月 | T22: =S22-R22 -> 0
B23: 2025年1月 | C23: 269836 | D23: 361916 | E23: 92080 | G23: 2025年12月 | H23: ='FY-2(月次)支出'!L3 -> 557359 | I23: ='FY-2(月次)収入'!L3 -> 703578.01 | J23: =I23-H23 -> 146219.01 | L23: 2026年12月 | M23: ='FY-3(月次)支出 '!L3 -> 409403 | N23: ='FY-3(月次)収入'!L3 -> 898415.79 | O23: =N23-M23 -> 489012.79 | Q23: 2027年12月 | T23: =S23-R23 -> 0
B24: 2025年2月 | C24: 235258 | D24: 374138 | E24: 138880 | G24: 2026年1月 | H24: ='FY-2(月次)支出'!M3 -> 821287 | I24: ='FY-2(月次)収入'!M3 -> 752868.15 | J24: =I24-H24 -> -68418.849 | L24: 2027年1月 | M24: ='FY-3(月次)支出 '!M3 -> 499403 | N24: ='FY-3(月次)収入'!M3 -> 775574.21 | O24: =N24-M24 -> 276171.21 | Q24: 2028年1月 | T24: =S24-R24 -> 0
B25: 2025年3月 | C25: 263558 | D25: 309616 | E25: 46058 | G25: 2026年2月 | H25: ='FY-2(月次)支出'!N3 -> 382867 | I25: ='FY-2(月次)収入'!N3 -> 581951.13 | J25: =I25-H25 -> 199084.13 | L25: 2027年2月 | M25: ='FY-3(月次)支出 '!N3 -> 409371 | N25: ='FY-3(月次)収入'!N3 -> 1161464.2 | O25: =N25-M25 -> 752093.16 | Q25: 2028年2月 | T25: =S25-R25 -> 0
B26: 2025年4月 | C26: 330716 | D26: 362471 | E26: 31755 | G26: 2026年3月 | H26: ='FY-2(月次)支出'!O3 -> 570863 | I26: ='FY-2(月次)収入'!O3 -> 773052.25 | J26: =I26-H26 -> 202189.25 | L26: 2027年3月 | M26: ='FY-3(月次)支出 '!O3 -> 499403 | N26: ='FY-3(月次)収入'!O3 -> 747941.85 | O26: =N26-M26 -> 248538.85 | Q26: 2028年3月 | T26: =S26-R26 -> 0
B27: 合計 | C27: =SUM(C15:C26) -> 3046227 | D27: =SUM(D15:D26) -> 4172715 | E27: =SUM(E15:E26) -> 1126488 | G27: 合計 | H27: =SUM(H15:H26) -> 5512188 | I27: =SUM(I15:I26) -> 6192587.7 | J27: =SUM(J15:J26) -> 680399.72 | L27: 合計 | M27: =SUM(M15:M26) -> 6089552 | N27: =SUM(N15:N26) -> 9291559 | O27: =SUM(O15:O26) -> 3202007 | Q27: 合計 | R27: =SUM(R15:R26) -> 0 | S27: =SUM(S15:S26) -> 0 | T27: =SUM(T15:T26) -> 0
B29: (FY-3)年間予算達成率
B30: 【 予実対比 】 | D30: 2026年4月 | E30: 2026年5月 | F30: 2026年6月 | G30: 2026年7月 | H30: 2026年8月 | I30: 2026年9月 | J30: 2026年10月 | K30: 2026年11月 | L30: 2026年12月 | M30: 2027年1月 | N30: 2027年2月 | O30: 2027年3月 | P30: 合計 | Q30: 達成率
B31: 予算 | C31: 収入 | D31: 556810.19 | E31: 562468.19 | F31: 778785.69 | G31: 759686.75 | H31: 756528.31 | I31: 1173447.2 | J31: 769052.83 | K31: 1173388.3 | L31: 900997.58 | M31: 778205.15 | N31: 1164875.1 | O31: 751402.69 | P31: =IF(D31="","",SUM(D31:O31)) -> 10125648 | Q31: /
C32: 支出 | D32: 472674 | E32: 437674 | F32: 527674 | G32: 607674 | H32: 617674 | I32: 877674 | J32: 557674 | K32: 657674 | L32: 437674 | M32: 527674 | N32: 437642 | O32: 527674 | P32: =IF(D32="","",SUM(D32:O32)) -> 6687056 | Q32: /
C33: 収支 | D33: =D31-D32 -> 84136.19 | E33: =E31-E32 -> 124794.19 | F33: =F31-F32 -> 251111.69 | G33: =G31-G32 -> 152012.75 | H33: =H31-H32 -> 138854.31 | I33: =I31-I32 -> 295773.24 | J33: =J31-J32 -> 211378.83 | K33: =K31-K32 -> 515714.31 | ... O33: =O31-O32 -> 223728.69 | P33: =IF(D33="","",SUM(D33:O33)) -> 3438592.1 | Q33: /
B34: 実績 | C34: 収入 | D34: =N15 -> 575013.96 | E34: =N16 -> 518059.08 | F34: =N17 -> 549667.74 | G34: =N18 -> 538747.85 | H34: =N19 -> 745190.1 | I34: =N20 -> 861996.07 | J34: =N21 -> 757549.43 | K34: =N22 -> 1161938.8 | L34: =N23 -> 898415.79 | M34: =N24 -> 775574.21 | N34: =N25 -> 1161464.2 | O34: =N26 -> 747941.85 | P34: =IF(D34="","",SUM(D34:O34)) -> 9291559 | Q34: =P34/P31 -> 0.91762611
C35: 支出 | D35: =M15 -> 440344 | E35: =M16 -> 447333 | F35: =M17 -> 392616 | G35: =M18 -> 494717 | H35: =M19 -> 588753 | I35: =M20 -> 849403 | J35: =M21 -> 529403 | K35: =M22 -> 529403 | L35: =M23 -> 409403 | M35: =M24 -> 499403 | N35: =M25 -> 409371 | O35: =M26 -> 499403 | P35: =IF(D35="","",SUM(D35:O35)) -> 6089552 | Q35: =P35/P32 -> 0.91064768
C36: 収支 | D36: =D34-D35 -> 134669.96 | E36: =E34-E35 -> 70726.075 | F36: =F34-F35 -> 157051.74 | G36: =G34-G35 -> 44030.85 | H36: =H34-H35 -> 156437.1 | I36: =I34-I35 -> 12593.07 | J36: =J34-J35 -> 228146.43 | K36: =K34-K35 -> 632535.77 | ... O36: =O34-O35 -> 248538.85 | P36: =IF(D36="","",SUM(D36:O36)) -> 3202007 | Q36: =P36/P33 -> 0.93119711
B37: 差異 (実績-予算) | C37: 収入 | D37: =D34-D31 -> 18203.767 | E37: =E34-E31 -> -44409.115 | F37: =F34-F31 -> -229117.94 | G37: =G34-G31 -> -220938.9 | H37: =H34-H31 -> -11338.206 | I37: =I34-I31 -> -311451.17 | J37: =J34-J31 -> -11503.402 | K37: =K34-K31 -> -11449.537 | ... O37: =O34-O31 -> -3460.84 | P37: =IF(D37="","",SUM(D37:O37)) -> -834089.05 | Q37: /
C38: 支出 | D38: =D35-D32 -> -32330 | E38: =E35-E32 -> 9659 | F38: =F35-F32 -> -135058 | G38: =G35-G32 -> -112957 | H38: =H35-H32 -> -28921 | I38: =I35-I32 -> -28271 | J38: =J35-J32 -> -28271 | K38: =K35-K32 -> -128271 | ... O38: =O35-O32 -> -28271 | P38: =IF(D38="","",SUM(D38:O38)) -> -597504 | Q38: /
C39: 収支 | D39: =D36-D33 -> 50533.767 | E39: =E36-E33 -> -54068.115 | F39: =F36-F33 -> -94059.945 | G39: =G36-G33 -> -107981.9 | H39: =H36-H33 -> 17582.794 | I39: =I36-I33 -> -283180.17 | J39: =J36-J33 -> 16767.598 | K39: =K36-K33 -> 116821.46 | ... O39: =O36-O33 -> 24810.16 | P39: =IF(D39="","",SUM(D39:O39)) -> -236585.05 | Q39: /
B41: (FY-2)年間予算達成率
B42: 【 予実対比 】 | D42: 2025年4月 | E42: 2025年5月 | F42: 2025年6月 | G42: 2025年7月 | H42: 2025年8月 | I42: 2025年9月 | J42: 2025年10月 | K42: 2025年11月 | L42: 2025年12月 | M42: 2026年1月 | N42: 2026年2月 | O42: 2026年3月 | P42: 合計 | Q42: 達成率
B43: 予算 | C43: 収入 | D43: 347771 | E43: 275744 | F43: 0 | G43: 388759 | H43: 388759 | I43: 388759 | J43: 388759 | K43: 388759 | L43: 448759 | M43: 388759 | N43: 388759 | O43: 388759 | P43: =IF(D43="","",SUM(D43:O43)) -> 4182346 | Q43: /
C44: 支出 | D44: 337608 | E44: 423456 | F44: 297375 | G44: 285200 | H44: 300200 | I44: 335200 | J44: 305200 | K44: 300200 | L44: 340200 | M44: 305200 | N44: 300200 | O44: 300200 | P44: =IF(D44="","",SUM(D44:O44)) -> 3830239 | Q44: /
C45: 収支 | D45: =D43-D44 -> 10163 | E45: =E43-E44 -> -147712 | F45: =F43-F44 -> -297375 | G45: =G43-G44 -> 103559 | H45: =H43-H44 -> 88559 | I45: =I43-I44 -> 53559 | J45: =J43-J44 -> 83559 | K45: =K43-K44 -> 88559 | ... O45: =O43-O44 -> 88559 | P45: =IF(D45="","",SUM(D45:O45)) -> 352107 | Q45: /
B46: 実績 | C46: 収入 | D46: =I15 -> 362756 | E46: =I16 -> 280024 | F46: =I17 -> 68896 | G46: =I18 -> 473086 | H46: =I19 -> 502474 | I46: =I20 -> 584444 | J46: =I21 -> 524857 | K46: =I22 -> 584601.18 | L46: =I23 -> 703578.01 | M46: =I24 -> 752868.15 | N46: =I25 -> 581951.13 | O46: =I26 -> 773052.25 | P46: =IF(D46="","",SUM(D46:O46)) -> 6192587.7 | Q46: =P46/P43 -> 1.4806493
C47: 支出 | D47: =H15 -> 328579 | E47: =H16 -> 458043 | F47: =H17 -> 320775 | G47: =H18 -> 314993 | H47: =H19 -> 335534 | I47: =H20 -> 340477 | J47: =H21 -> 514909 | K47: =H22 -> 566502 | L47: =H23 -> 557359 | M47: =H24 -> 821287 | N47: =H25 -> 382867 | O47: =H26 -> 570863 | P47: =IF(D47="","",SUM(D47:O47)) -> 5512188 | Q47: =P47/P44 -> 1.4391238
C48: 収支 | D48: =D46-D47 -> 34177 | E48: =E46-E47 -> -178019 | F48: =F46-F47 -> -251879 | G48: =G46-G47 -> 158093 | H48: =H46-H47 -> 166940 | I48: =I46-I47 -> 243967 | J48: =J46-J47 -> 9948 | K48: =K46-K47 -> 18099.183 | ... O48: =O46-O47 -> 202189.25 | P48: =IF(D48="","",SUM(D48:O48)) -> 680399.72 | Q48: =P48/P45 -> 1.9323664
B49: 差異 (実績-予算) | C49: 収入 | D49: =D46-D43 -> 14985 | E49: =E46-E43 -> 4280 | F49: =F46-F43 -> 68896 | G49: =G46-G43 -> 84327 | H49: =H46-H43 -> 113715 | I49: =I46-I43 -> 195685 | J49: =J46-J43 -> 136098 | K49: =K46-K43 -> 195842.18 | ... O49: =O46-O43 -> 384293.25 | P49: =IF(D49="","",SUM(D49:O49)) -> 2010241.7 | Q49: /
...

Sheet (FY-2)資産管理
B2: ※月末時点の情報を入力 | C2: ※確定 | D2: ※確定 | E2: ※確定 | F2: ※確定 | G2: ※確定 | H2: ※確定 | I2: ※確定 | J2: ※確定 | K2: ※確定 | L2: ※確定 | M2: ※確定 | N2: ※確定
B3: (FY-2)資産管理表 | C3: 2025年4月 | D3: 2025年5月 | E3: 2025年6月 | F3: 2025年7月 | G3: 2025年8月 | H3: 2025年9月 | I3: 2025年10月 | J3: 2025年11月 | K3: 2025年12月 | L3: 2026年1月 | M3: 2026年2月 | N3: 2026年3月 | O3: 合計 | P3: 平均
A4: ※ | B4: 銀行預金 | C4: =SUM(C5:C8) -> 109418 | D4: =SUM(D5:D8) -> 163655 | E4: =SUM(E5:E8) -> 48459 | F4: =SUM(F5:F8) -> 20957 | G4: =SUM(G5:G8) -> 21010 | H4: =SUM(H5:H8) -> 25539 | I4: =SUM(I5:I8) -> 48910 | J4: =SUM(J5:J8) -> 30359 | ... N4: =SUM(N5:N8) -> 166502 | O4: =SUM(C4:N4) -> 1031073 | P4: =IFERROR(AVERAGE(C4:N4),"") -> 85922.75
B5: ①みずほ銀行／浜松町支店 | C5: =みずほ!J33 -> 101400 | D5: =みずほ!J64 -> 110380 | E5: =みずほ!J94 -> 35621 | F5: =みずほ!J125 -> 14033 | G5: =みずほ!J156 -> 13905 | H5: =みずほ!J186 -> 13900 | I5: =みずほ!J217 -> 34634 | J5: =みずほ!J247 -> 22620 | K5: =みずほ!J278 -> 58393 | L5: =みずほ!J309 -> 34755 | M5: =みずほ!J337 -> 23123 | N5: =みずほ!J368 -> 30684 | O5: =SUM(C5:N5) -> 493448 | P5: =IFERROR(AVERAGE(C5:N5),"") -> 41120.667
B6: ②三菱UFJ銀行／国立支店 | C6: =UFJ!I33 -> 8018 | D6: =UFJ!I64 -> 53275 | E6: =UFJ!I94 -> 12838 | F6: =UFJ!I125 -> 6924 | G6: =UFJ!I156 -> 325 | H6: =UFJ!I186 -> 325 | I6: =UFJ!I217 -> 325 | J6: =UFJ!I247 -> 325 | K6: =UFJ!I278 -> 325 | L6: =UFJ!I309 -> 325 | M6: =UFJ!I337 -> 0 | N6: =UFJ!I368 -> 0 | O6: =SUM(C6:N6) -> 83005 | P6: =IFERROR(AVERAGE(C6:N6),"") -> 6917.0833
B7: ③三井住友銀行／オリーブECRU(871)支店 | C7: =三井住友!I33 -> / | D7: =三井住友!I64 -> / | E7: =三井住友!I94 -> / | F7: =三井住友!I125 -> 0 | G7: =三井住友!I156 -> 6780 | H7: =三井住友!I186 -> 11314 | I7: =三井住友!I217 -> 13951 | J7: =三井住友!I247 -> 7414 | K7: =三井住友!I278 -> 27387 | L7: =三井住友!I309 -> 172576 | M7: =三井住友!I337 -> 78526 | N7: =三井住友!I368 -> 110842 | O7: =SUM(C7:N7) -> 428790 | P7: =IFERROR(AVERAGE(C7:N7),"") -> 47643.333
B8: ④楽天銀行／ベース支店 | C8: 0 | D8: 0 | E8: 0 | F8: 0 | G8: 0 | H8: 0 | I8: 0 | J8: 0 | K8: 0 | L8: 428 | M8: =楽天!J337 -> 426 | N8: =楽天!J368 -> 24976 | O8: =SUM(C8:N8) -> 25830 | P8: =IFERROR(AVERAGE(C8:N8),"") -> 2152.5
A9: ※ | B9: キャッシュレス残高 | C9: =SUM(C10:C19) -> 0 | D9: =SUM(D10:D19) -> 0 | E9: =SUM(E10:E19) -> 0 | F9: =SUM(F10:F19) -> 0 | G9: =SUM(G10:G19) -> 0 | H9: =SUM(H10:H19) -> 0 | I9: =SUM(I10:I19) -> 48221 | J9: =SUM(J10:J19) -> 59786 | ... N9: =SUM(N10:N19) -> 44002 | O9: =SUM(C9:N9) -> 288124 | P9: =IFERROR(AVERAGE(C9:N9),"") -> 24010.333
B10: ①PASMO残高 | C10: - | D10: - | E10: - | F10: - | G10: - | H10: - | I10: 19203 | J10: 19364 | K10: 18377 | L10: 13333 | M10: 19509 | N10: 2696 | O10: =SUM(C10:N10) -> 92482 | P10: =IFERROR(AVERAGE(C10:N10),"") -> 15413.667
B11: ②ANAPay残高 | C11: - | D11: - | E11: - | F11: - | G11: - | H11: - | I11: 8048 | J11: 21460 | K11: 870 | L11: 9160 | M11: 2740 | N11: 15740 | O11: =SUM(C11:N11) -> 58018 | P11: =IFERROR(AVERAGE(C11:N11),"") -> 9669.6667
B12: ③JALPay残高 | C12: - | D12: - | E12: - | F12: - | G12: - | H12: - | I12: 2 | J12: 0 | K12: 0 | L12: 0 | M12: 0 | N12: 0 | O12: =SUM(C12:N12) -> 2 | P12: =IFERROR(AVERAGE(C12:N12),"") -> 0.33333333
B13: ④PayPay残高 | C13: - | D13: - | E13: - | F13: - | G13: - | H13: - | I13: 5822 | J13: 9685 | K13: 17906 | L13: 11173 | M13: 309 | N13: 2980 | O13: =SUM(C13:N13) -> 47875 | P13: =IFERROR(AVERAGE(C13:N13),"") -> 7979.1667
B14: ⑤VポイントPay残高 | I14: 7693 | J14: 2798 | K14: 1126 | L14: 216 | M14: 216 | N14: 302 | O14: =SUM(C14:N14) -> 12351 | P14: =IFERROR(AVERAGE(C14:N14),"") -> 2058.5
B15: ⑥メルペイ残高 | I15: 1753 | J15: 381 | K15: 381 | L15: 381 | M15: 34 | N15: 34 | O15: =SUM(C15:N15) -> 2964 | P15: =IFERROR(AVERAGE(C15:N15),"") -> 494
B16: ⑦Pontaポイント | I16: 654 | J16: 657 | K16: 75 | L16: 533 | M16: 75 | N16: 86 | O16: =SUM(C16:N16) -> 2080 | P16: =IFERROR(AVERAGE(C16:N16),"") -> 346.66667
B17: ⑧dポイント | M17: 315 | N17: 5 | O17: =SUM(C17:N17) -> 320 | P17: =IFERROR(AVERAGE(C17:N17),"") -> 160
B18: ⑨PayPayポイント（自動運用） | C18: - | D18: - | E18: - | F18: - | G18: - | H18: - | I18: 4901 | J18: 5436 | K18: 7323 | L18: 14242 | M18: 17806 | N18: 22154 | O18: =SUM(C18:N18) -> 71862 | P18: =IFERROR(AVERAGE(C18:N18),"") -> 11977
B19: ICOCA残高 | C19: - | D19: - | E19: - | F19: - | G19: - | H19: - | I19: 145 | J19: 5 | K19: 5 | L19: 5 | M19: 5 | N19: 5 | O19: =SUM(C19:N19) -> 170 | P19: =IFERROR(AVERAGE(C19:N19),"") -> 28.333333
A20: ※ | B20: 暗号通貨(bitFlyer)*月末時点の総資産 | C20: 0 | D20: 0 | E20: 0 | F20: =F23+F26+F29 -> 6000 | G20: 12200 | H20: 18870 | I20: 23902 | J20: =J23+J26+J29 -> 6000 | K20: =K23+K26+K29 -> 6000 | L20: =L23+L26+L29 -> 0 | M20: =M23+M26+M29 -> 0 | N20: =N23+N26+N29 -> 0 | O20: =SUM(C20:N20) -> 72972 | P20: =IFERROR(AVERAGE(C20:N20),"") -> 6081
B21: 買い注文した額 | C21: / | D21: / | E21: / | F21: =F23+F26+F29 -> 6000 | G21: =G23+G26+G29 -> 6500 | H21: 6000 | I21: 6000 | J21: 6000 | K21: 6000 | L21: 0 | M21: 0 | N21: 0 | O21: =SUM(C21:N21) -> 36500 | P21: =IFERROR(AVERAGE(C21:N21),"") -> 4055.5556
B22: USD→JPY 為替 | C22: ¥149.93 / $1 | D22: ¥145.34 / $1 | E22: ¥144.51 / $1 | F22: ¥143.41 / $1 | G22: ¥147.32 / $1 | H22: ¥147.10 / $1 | I22: ¥152.50 / $1 | J22: ¥154.00 / $1 | K22: ¥155.80 / $1 | L22: 0 | M22: 0 | N22: 0 | O22: =SUM(C22:N22) -> 0 | P22: =IFERROR(AVERAGE(C22:N22),"") -> 0
B23: ①イーサリアム(Ethereum)/ETH | C23: 0 | D23: 0 | E23: 0 | F23: 3000 | G23: 3500 | H23: 3000 | I23: 5756 | J23: 3000 | K23: 4400 | L23: 0 | M23: 0 | N23: 0 | O23: =SUM(C23:N23) -> 22656 | P23: =IFERROR(AVERAGE(C23:N23),"") -> 1888
B24: ETH価格（JPY） | C24: 272950 | D24: 267320 | E24: 365460 | F24: 345190 | G24: 515970 | H24: 652915 | I24: 573675 | J24: 600833 | K24: 468144 | L24: 0 | M24: 0 | N24: 0 | O24: =SUM(C24:N24) -> 4062457 | P24: =IFERROR(AVERAGE(C24:N24),"") -> 338538.08
B25: ETH価格（USD） | C25: $1,822.14 | D25: $1,838.83 | E25: $2,529.32 | F25: $2,405.70 | G25: $3,508.6 | H25: $4,406.51 | I25: $3,762.46 | J25: $3,899.74 | K25: $2,842.8 | L25: 0 | M25: 0 | N25: 0 | O25: =SUM(C25:N25) -> 0 | P25: =IFERROR(AVERAGE(C25:N25),"") -> 0
B26: ②ビットコイン(Bitcoin)/BTC | C26: 0 | D26: 0 | E26: 0 | F26: 2000 | G26: 2000 | H26: 2000 | I26: 0 | J26: 2000 | K26: 1000 | L26: 0 | M26: 0 | N26: 0 | O26: =SUM(C26:N26) -> 9000 | P26: =IFERROR(AVERAGE(C26:N26),"") -> 750
B27: BTC価格（JPY） | C27: 12772240 | D27: 15217000 | E27: 15340000 | F27: 15349296 | G27: 16708900 | H27: 16100344 | I27: 16919257 | J27: 17025072 | K27: 14096354 | L27: 0 | M27: 0 | N27: 0 | O27: =SUM(C27:N27) -> 139528463 | P27: =IFERROR(AVERAGE(C27:N27),"") -> 11627372
B28: BTC価格（USD） | C28: $85,190 | D28: $104,638 | E28: $106,159 | F28: $106,800 | G28: $113,396 | H28: $109,216 | I28: $110,923 | J28: $110,660 | K28: $86,563.4 | L28: 0 | M28: 0 | N28: 0 | O28: =SUM(C28:N28) -> 0 | P28: =IFERROR(AVERAGE(C28:N28),"") -> 0
B29: ③エックスアールピー(XRP)/XRP | C29: 0 | D29: 0 | E29: 0 | F29: 1000 | G29: 1000 | H29: 1000 | I29: 244 | J29: 1000 | K29: 600 | L29: 0 | M29: 0 | N29: 0 | O29: =SUM(C29:N29) -> 4844 | P29: =IFERROR(AVERAGE(C29:N29),"") -> 403.66667
B30: XRP価格（JPY） | C30: 314 | D30: 368 | E30: 361 | F30: 400 | G30: 432 | H30: 411.89 | I30: 369.65 | J30: 388 | K30: 337.4 | L30: 0 | M30: 0 | N30: 0 | O30: =SUM(C30:N30) -> 3381.94 | P30: =IFERROR(AVERAGE(C30:N30),"") -> 281.82833
B31: XRP価格（USD） | C31: $2.10 | D31: $2.53 | E31: $2.50 | F31: $2.79 | G31: $2.94 | H31: $2.77 | I31: $2.43 | J31: $2.5 | K31: $2.05 | L31: 0 | M31: 0 | N31: 0 | O31: =SUM(C31:N31) -> 0 | P31: =IFERROR(AVERAGE(C31:N31),"") -> 0
A32: ※ | B32: 証券口座 | C32: =SUM(C33:C35) -> 0 | D32: =SUM(D33:D35) -> 0 | E32: =SUM(E33:E35) -> 0 | F32: =SUM(F33:F35) -> 0 | G32: =SUM(G33:G35) -> 0 | H32: =SUM(H33:H35) -> 0 | I32: =SUM(I33:I35) -> 0 | J32: =SUM(J33:J35) -> 0 | ... N32: =SUM(N33:N35) -> 0 | O32: =SUM(C32:N32) -> 94680 | P32: =IFERROR(AVERAGE(C32:N32),"") -> 7890
B33: ①楽天証券 | C33: 0 | D33: 0 | E33: 0 | F33: 0 | G33: 0 | H33: 0 | I33: 0 | J33: 0 | K33: 0 | L33: 94680 | M33: 0 | N33: 0 | O33: =SUM(C33:N33) -> 94680 | P33: =IFERROR(AVERAGE(C33:N33),"") -> 7890
B34: ② | C34: 0 | D34: 0 | E34: 0 | F34: 0 | G34: 0 | H34: 0 | I34: 0 | J34: 0 | K34: 0 | L34: 0 | M34: 0 | N34: 0 | O34: =SUM(C34:N34) -> 0 | P34: =IFERROR(AVERAGE(C34:N34),"") -> 0
B35: ③ | C35: 0 | D35: 0 | E35: 0 | F35: 0 | G35: 0 | H35: 0 | I35: 0 | J35: 0 | K35: 0 | L35: 0 | M35: 0 | N35: 0 | O35: =SUM(C35:N35) -> 0 | P35: =IFERROR(AVERAGE(C35:N35),"") -> 0
B36: 株式資産／国内株式 | C36: =SUM(C37:C39) -> 0 | D36: =SUM(D37:D39) -> 0 | E36: =SUM(E37:E39) -> 0 | F36: =SUM(F37:F39) -> 0 | G36: =SUM(G37:G39) -> 0 | H36: =SUM(H37:H39) -> 0 | I36: =SUM(I37:I39) -> 0 | J36: =SUM(J37:J39) -> 0 | ... N36: =SUM(N37:N39) -> 0 | O36: =SUM(C36:N36) -> 94680 | P36: =IFERROR(AVERAGE(C36:N36),"") -> 7890
B37: ①サンリオ | C37: 0 | D37: 0 | E37: 0 | F37: 0 | G37: 0 | H37: 0 | I37: 0 | J37: 0 | K37: 0 | L37: 94680 | M37: 0 | N37: 0 | O37: =SUM(C37:N37) -> 94680 | P37: =IFERROR(AVERAGE(C37:N37),"") -> 7890
B38: ② | C38: 0 | D38: 0 | E38: 0 | F38: 0 | G38: 0 | H38: 0 | I38: 0 | J38: 0 | K38: 0 | L38: 0 | M38: 0 | N38: 0 | O38: =SUM(C38:N38) -> 0 | P38: =IFERROR(AVERAGE(C38:N38),"") -> 0
B39: ③ | C39: 0 | D39: 0 | E39: 0 | F39: 0 | G39: 0 | H39: 0 | I39: 0 | J39: 0 | K39: 0 | L39: 0 | M39: 0 | N39: 0 | O39: =SUM(C39:N39) -> 0 | P39: =IFERROR(AVERAGE(C39:N39),"") -> 0
B40: 株式資産／米国株式 | C40: =SUM(C41:C43) -> 0 | D40: =SUM(D41:D43) -> 0 | E40: =SUM(E41:E43) -> 0 | F40: =SUM(F41:F43) -> 0 | G40: =SUM(G41:G43) -> 0 | H40: =SUM(H41:H43) -> 0 | I40: =SUM(I41:I43) -> 0 | J40: =SUM(J41:J43) -> 0 | ... N40: =SUM(N41:N43) -> 0 | O40: =SUM(C40:N40) -> 0 | P40: =IFERROR(AVERAGE(C40:N40),"") -> 0
B41: ① | C41: 0 | D41: 0 | E41: 0 | F41: 0 | G41: 0 | H41: 0 | I41: 0 | J41: 0 | K41: 0 | L41: 0 | M41: 0 | N41: 0 | O41: =SUM(C41:N41) -> 0 | P41: =IFERROR(AVERAGE(C41:N41),"") -> 0
...

Sheet (FY-3)資産管理
B2: ※月末時点の情報を入力 | C2: ※確定 | D2: ※確定 | E2: ※確定 | F2: 未確定 | G2: 未確定 | H2: 未確定 | I2: 未確定 | J2: 未確定 | K2: 未確定 | L2: 未確定 | M2: 未確定 | N2: 未確定
B3: (FY-3)資産管理表 | C3: 2026年4月 | D3: 2026年5月 | E3: 2026年6月 | F3: 2026年7月 | G3: 2026年8月 | H3: 2026年9月 | I3: 2026年10月 | J3: 2026年11月 | K3: 2026年12月 | L3: 2027年1月 | M3: 2027年2月 | N3: 2027年3月 | O3: 平均
A4: ※ | B4: 銀行預金 | C4: =SUM(C5:C8) -> 931 | D4: =SUM(D5:D8) -> 53860 | E4: =SUM(E5:E8) -> 151188 | F4: =SUM(F5:F8) -> 293091 | G4: =SUM(G5:G8) -> 462994 | H4: =SUM(H5:H8) -> 582897 | I4: =SUM(I5:I8) -> 702800 | J4: =SUM(J5:J8) -> 822703 | ... N4: =SUM(N5:N8) -> 1302315 | O4: =IFERROR(AVERAGE(C4:N4),"") -> 630025.5
B5: ①みずほ銀行／浜松町支店 | C5: =みずほ!J398 -> 8 | D5: =みずほ!J429 -> 32259 | E5: =みずほ!J459 -> 72765 | F5: =みずほ!J490 -> 252668 | G5: =みずほ!J521 -> 422571 | H5: =みずほ!J551 -> 442474 | I5: =みずほ!J582 -> 462377 | J5: =みずほ!J612 -> 482280 | K5: =みずほ!J643 -> 502183 | L5: =みずほ!J674 -> 522086 | M5: =みずほ!J702 -> 541989 | N5: =みずほ!J733 -> 561892 | O5: =IFERROR(AVERAGE(C5:N5),"") -> 357962.67
B6: ②三菱UFJ銀行／国立支店 | C6: =UFJ!I398 -> 0 | D6: =UFJ!I429 -> 0 | E6: =UFJ!I459 -> 0 | F6: =UFJ!I490 -> 0 | G6: =UFJ!I521 -> 0 | H6: =UFJ!I551 -> 0 | I6: =UFJ!I582 -> 0 | J6: =UFJ!I612 -> 0 | K6: =UFJ!I643 -> 0 | L6: =UFJ!I674 -> 0 | M6: =UFJ!I702 -> 0 | N6: =UFJ!I733 -> 0 | O6: =IFERROR(AVERAGE(C6:N6),"") -> 0
B7: ③三井住友銀行／オリーブECRU(871)支店 | C7: =三井住友!I398 -> 909 | D7: =三井住友!I429 -> 4210 | E7: =三井住友!I459 -> 57550 | F7: =三井住友!I490 -> 19550 | G7: =三井住友!I521 -> 19550 | H7: =三井住友!I551 -> 119550 | I7: =三井住友!I582 -> 219550 | J7: =三井住友!I612 -> 319550 | K7: =三井住友!I643 -> 419550 | L7: =三井住友!I674 -> 519550 | M7: =三井住友!I702 -> 619550 | N7: =三井住友!I733 -> 719550 | O7: =IFERROR(AVERAGE(C7:N7),"") -> 253218.25
B8: ④楽天銀行／ベース支店 | C8: =楽天!J398 -> 14 | D8: =楽天!J429 -> 17391 | E8: =楽天!J459 -> 20873 | F8: =楽天!J490 -> 20873 | G8: =楽天!J521 -> 20873 | H8: =楽天!J551 -> 20873 | I8: =楽天!J582 -> 20873 | J8: =楽天!J612 -> 20873 | K8: =楽天!J643 -> 20873 | L8: =楽天!J674 -> 20873 | M8: =楽天!J702 -> 20873 | N8: =楽天!J733 -> 20873 | O8: =IFERROR(AVERAGE(C8:N8),"") -> 18844.583
A9: ※ | B9: キャッシュレス残高 | C9: =SUM(C10:C19) -> 52921 | D9: =SUM(D10:D19) -> 70655 | E9: =SUM(E10:E19) -> 22611 | F9: =SUM(F10:F19) -> 0 | G9: =SUM(G10:G19) -> 0 | H9: =SUM(H10:H19) -> 0 | I9: =SUM(I10:I19) -> 145 | J9: =SUM(J10:J19) -> 5 | ... N9: =SUM(N10:N19) -> 5 | O9: =IFERROR(AVERAGE(C9:N9),"") -> 12256.167
B10: ①PASMO残高 | C10: 10000 | D10: 18283 | E10: 17924 | O10: =IFERROR(AVERAGE(C10:N10),"") -> 15402.333
B11: ②ANAPay残高 | C11: 5000 | D11: 6860 | E11: 2060 | O11: =IFERROR(AVERAGE(C11:N11),"") -> 4640
B12: ③JALPay残高 | C12: 0 | D12: 0 | E12: 0 | O12: =IFERROR(AVERAGE(C12:N12),"") -> 0
B13: ④PayPay残高 | C13: 273 | D13: 4575 | E13: 9 | O13: =IFERROR(AVERAGE(C13:N13),"") -> 1619
B14: ⑤VポイントPay残高 | C14: 302 | D14: 302 | E14: 302 | O14: =IFERROR(AVERAGE(C14:N14),"") -> 302
B15: ⑥メルペイ残高 | C15: 34 | D15: 34 | E15: 34 | O15: =IFERROR(AVERAGE(C15:N15),"") -> 34
B16: ⑦Pontaポイント | C16: 607 | D16: 7 | E16: 109 | O16: =IFERROR(AVERAGE(C16:N16),"") -> 241
B17: ⑧dポイント | C17: 1105 | D17: 65 | E17: 65 | O17: =IFERROR(AVERAGE(C17:N17),"") -> 411.66667
B18: ⑨PayPayポイント（自動運用） | C18: 35600 | D18: 40529 | E18: 2108 | O18: =IFERROR(AVERAGE(C18:N18),"") -> 26079
B19: ICOCA残高 | C19: - | D19: - | E19: - | F19: - | G19: - | H19: - | I19: 145 | J19: 5 | K19: 5 | L19: 5 | M19: 722 | N19: 5 | O19: =IFERROR(AVERAGE(C19:N19),"") -> 147.83333
A20: ※ | B20: 暗号通貨(bitFlyer)*月末時点の総資産 | C20: 0 | D20: 0 | E20: 0 | F20: =F23+F26+F29 -> 6000 | G20: 12200 | H20: 18870 | I20: 23902 | J20: =J23+J26+J29 -> 6000 | K20: =K23+K26+K29 -> 6000 | L20: =L23+L26+L29 -> 0 | M20: =M23+M26+M29 -> 0 | N20: =N23+N26+N29 -> 0 | O20: =IFERROR(AVERAGE(C20:N20),"") -> 6081
B21: 買い注文した額 | C21: / | D21: / | E21: / | F21: =F23+F26+F29 -> 6000 | G21: =G23+G26+G29 -> 6500 | H21: 6000 | I21: 6000 | J21: 6000 | K21: 6000 | L21: 0 | M21: 0 | N21: =N23+N26+N29 -> 0 | O21: =IFERROR(AVERAGE(C21:N21),"") -> 4055.5556
B22: USD→JPY 為替 | C22: ¥149.93 / $1 | D22: ¥145.34 / $1 | E22: ¥144.51 / $1 | F22: ¥143.41 / $1 | G22: ¥147.32 / $1 | H22: ¥147.10 / $1 | I22: ¥152.50 / $1 | J22: ¥154.00 / $1 | K22: ¥155.80 / $1 | L22: 0 | M22: 0 | O22: =IFERROR(AVERAGE(C22:N22),"") -> 0
B23: ①イーサリアム(Ethereum)/ETH | C23: 0 | D23: 0 | E23: 0 | F23: 3000 | G23: 3500 | H23: 3000 | I23: 5756 | J23: 3000 | K23: 4400 | L23: 0 | M23: 0 | N23: 0 | O23: =IFERROR(AVERAGE(C23:N23),"") -> 1888
B24: ETH価格（JPY） | C24: 272950 | D24: 267320 | E24: 365460 | F24: 345190 | G24: 515970 | H24: 652915 | I24: 573675 | J24: 600833 | K24: 468144 | L24: 0 | M24: 0 | O24: =IFERROR(AVERAGE(C24:N24),"") -> 369314.27
B25: ETH価格（USD） | C25: $1,822.14 | D25: $1,838.83 | E25: $2,529.32 | F25: $2,405.70 | G25: $3,508.6 | H25: $4,406.51 | I25: $3,762.46 | J25: $3,899.74 | K25: $2,842.8 | L25: 0 | M25: 0 | O25: =IFERROR(AVERAGE(C25:N25),"") -> 0
B26: ②ビットコイン(Bitcoin)/BTC | C26: 0 | D26: 0 | E26: 0 | F26: 2000 | G26: 2000 | H26: 2000 | I26: 0 | J26: 2000 | K26: 1000 | L26: 0 | M26: 0 | N26: 0 | O26: =IFERROR(AVERAGE(C26:N26),"") -> 750
B27: BTC価格（JPY） | C27: 12772240 | D27: 15217000 | E27: 15340000 | F27: 15349296 | G27: 16708900 | H27: 16100344 | I27: 16919257 | J27: 17025072 | K27: 14096354 | L27: 0 | M27: 0 | O27: =IFERROR(AVERAGE(C27:N27),"") -> 12684406
B28: BTC価格（USD） | C28: $85,190 | D28: $104,638 | E28: $106,159 | F28: $106,800 | G28: $113,396 | H28: $109,216 | I28: $110,923 | J28: $110,660 | K28: $86,563.4 | L28: 0 | M28: 0 | O28: =IFERROR(AVERAGE(C28:N28),"") -> 0
B29: ③エックスアールピー(XRP)/XRP | C29: 0 | D29: 0 | E29: 0 | F29: 1000 | G29: 1000 | H29: 1000 | I29: 244 | J29: 1000 | K29: 600 | L29: 0 | M29: 0 | N29: 0 | O29: =IFERROR(AVERAGE(C29:N29),"") -> 403.66667
B30: XRP価格（JPY） | C30: 314 | D30: 368 | E30: 361 | F30: 400 | G30: 432 | H30: 411.89 | I30: 369.65 | J30: 388 | K30: 337.4 | L30: 0 | M30: 0 | O30: =IFERROR(AVERAGE(C30:N30),"") -> 307.44909
B31: XRP価格（USD） | C31: $2.10 | D31: $2.53 | E31: $2.50 | F31: $2.79 | G31: $2.94 | H31: $2.77 | I31: $2.43 | J31: $2.5 | K31: $2.05 | L31: 0 | M31: 0 | O31: =IFERROR(AVERAGE(C31:N31),"") -> 0
A32: ※ | B32: 証券口座 | C32: =SUM(C33:C35) -> 0 | D32: =SUM(D33:D35) -> 0 | E32: =SUM(E33:E35) -> 0 | F32: =SUM(F33:F35) -> 0 | G32: =SUM(G33:G35) -> 0 | H32: =SUM(H33:H35) -> 0 | I32: =SUM(I33:I35) -> 0 | J32: =SUM(J33:J35) -> 0 | ... N32: =SUM(N33:N35) -> 0 | O32: =IFERROR(AVERAGE(C32:N32),"") -> 7890
B33: ①楽天証券 | C33: 0 | D33: 0 | E33: 0 | F33: 0 | G33: 0 | H33: 0 | I33: 0 | J33: 0 | K33: 0 | L33: 94680 | M33: 0 | N33: 0 | O33: =IFERROR(AVERAGE(C33:N33),"") -> 7890
B34: ② | C34: 0 | D34: 0 | E34: 0 | F34: 0 | G34: 0 | H34: 0 | I34: 0 | J34: 0 | K34: 0 | L34: 0 | M34: 0 | N34: 0 | O34: =IFERROR(AVERAGE(C34:N34),"") -> 0
B35: ③ | C35: 0 | D35: 0 | E35: 0 | F35: 0 | G35: 0 | H35: 0 | I35: 0 | J35: 0 | K35: 0 | L35: 0 | M35: 0 | N35: 0 | O35: =IFERROR(AVERAGE(C35:N35),"") -> 0
B36: 株式資産／国内株式 | C36: =SUM(C37:C39) -> 0 | D36: =SUM(D37:D39) -> 0 | E36: =SUM(E37:E39) -> 0 | F36: =SUM(F37:F39) -> 0 | G36: =SUM(G37:G39) -> 0 | H36: =SUM(H37:H39) -> 0 | I36: =SUM(I37:I39) -> 0 | J36: =SUM(J37:J39) -> 0 | ... N36: =SUM(N37:N39) -> 0 | O36: =IFERROR(AVERAGE(C36:N36),"") -> 7890
B37: ①サンリオ | C37: 0 | D37: 0 | E37: 0 | F37: 0 | G37: 0 | H37: 0 | I37: 0 | J37: 0 | K37: 0 | L37: 94680 | M37: 0 | N37: 0 | O37: =IFERROR(AVERAGE(C37:N37),"") -> 7890
B38: ② | C38: 0 | D38: 0 | E38: 0 | F38: 0 | G38: 0 | H38: 0 | I38: 0 | J38: 0 | K38: 0 | L38: 0 | M38: 0 | N38: 0 | O38: =IFERROR(AVERAGE(C38:N38),"") -> 0
B39: ③ | C39: 0 | D39: 0 | E39: 0 | F39: 0 | G39: 0 | H39: 0 | I39: 0 | J39: 0 | K39: 0 | L39: 0 | M39: 0 | N39: 0 | O39: =IFERROR(AVERAGE(C39:N39),"") -> 0
B40: 株式資産／米国株式 | C40: =SUM(C41:C43) -> 0 | D40: =SUM(D41:D43) -> 0 | E40: =SUM(E41:E43) -> 0 | F40: =SUM(F41:F43) -> 0 | G40: =SUM(G41:G43) -> 0 | H40: =SUM(H41:H43) -> 0 | I40: =SUM(I41:I43) -> 0 | J40: =SUM(J41:J43) -> 0 | ... N40: =SUM(N41:N43) -> 0 | O40: =IFERROR(AVERAGE(C40:N40),"") -> 0
B41: ① | C41: 0 | D41: 0 | E41: 0 | F41: 0 | G41: 0 | H41: 0 | I41: 0 | J41: 0 | K41: 0 | L41: 0 | M41: 0 | N41: 0 | O41: =IFERROR(AVERAGE(C41:N41),"") -> 0
...

Sheet 5か年PL
D1: 前月比 | F1: =F5-E5 -> 96503 | G1: =G5-F5 -> -50436 | H1: =H5-G5 -> 12000 | I1: =I5-H5 -> -22000 | J1: =J5-I5 -> 50020 | K1: =K5-J5 -> 3980 | L1: =L5-K5 -> -54000 | M1: =M5-L5 -> 50300 | ... BK1: =BK5-BJ5 -> -50000
E2: ※確定 | F2: ※確定 | G2: ※確定 | H2: ※確定 | I2: ※確定 | J2: ※確定 | K2: ※確定 | L2: ※確定 | M2: ※確定 | N2: ※確定 | O2: ※確定 | P2: ※確定 | Q2: ※確定 | R2: ※確定 | S2: ※確定 | T2: ※確定 | U2: ※確定 | V2: ※確定 | W2: ※確定 | X2: ※確定 | Y2: ※確定 | Z2: ※確定 | AA2: ※確定 | AB2: ※確定 | AC2: ※確定 | AD2: 未確定 | AE2: 未確定 | AF2: 未確定 | AG2: 未確定 | AH2: 未確定 | AI2: 未確定 | AJ2: 未確定 | AK2: 未確定 | AL2: 未確定 | AM2: 未確定 | AN2: 未確定 | AO2: 未確定 | AP2: 未確定 | AQ2: 未確定 | AR2: 未確定 | AS2: 未確定 | AT2: 未確定 | AU2: 未確定 | AV2: 未確定 | AW2: 未確定 | AX2: 未確定 | AY2: 未確定 | AZ2: 未確定 | BA2: 未確定 | BB2: 未確定 | BC2: 未確定 | BD2: 未確定 | BE2: 未確定 | BF2: 未確定 | BG2: 未確定 | BH2: 未確定 | BI2: 未確定 | BJ2: 未確定 | BK2: 未確定 | BL2: E～O | BN2: P～AA | BP2: AB～AM | BR2: AN～AY | BT2: AZ～BK
C3: 個人用PL | E3: FY-1（2024年5月～2025年3月） | P3: FY-2（2025年4月～2026年3月） | AB3: FY-3（2026年4月～2027年3月） | AN3: FY-4（2027年4月～2028年3月） | AZ3: FY-5（2028年4月～2029年3月） | BL3: FY-1 | BN3: FY-2 | BP3: FY-3 | BR3: FY-4 | BT3: FY-5
C4: 大項目 | D4: 小項目 | E4: 5月 | F4: 6月 | G4: 7月 | H4: 8月 | I4: 9月 | J4: 10月 | K4: 11月 | L4: 12月 | M4: 1月 | N4: 2月 | O4: 3月 | P4: 4月 | Q4: 5月 | R4: 6月 | S4: 7月 | T4: 8月 | U4: 9月 | V4: 10月 | W4: 11月 | X4: 12月 | Y4: 1月 | Z4: 2月 | AA4: 3月 | AB4: 4月 | AC4: 5月 | AD4: 6月 | AE4: 7月 | AF4: 8月 | AG4: 9月 | AH4: 10月 | AI4: 11月 | AJ4: 12月 | AK4: 1月 | AL4: 2月 | AM4: 3月 | AN4: 4月 | AO4: 5月 | AP4: 6月 | AQ4: 7月 | AR4: 8月 | AS4: 9月 | AT4: 10月 | AU4: 11月 | AV4: 12月 | AW4: 1月 | AX4: 2月 | AY4: 3月 | AZ4: 4月 | BA4: 5月 | BB4: 6月 | BC4: 7月 | BD4: 8月 | BE4: 9月 | BF4: 10月 | BG4: 11月 | BH4: 12月 | BI4: 1月 | BJ4: 2月 | BK4: 3月 | BL4: 通期 | BM4: (昨対比) | BN4: 通期 | BO4: (昨対比) | BP4: 通期 | BQ4: (昨対比) | BR4: 通期 | BS4: (昨対比) | BT4: 通期 | BU4: (昨対比)
C5: 収入 | D5: 合計 | E5: =SUM(E6:E10) -> 365933 | F5: =SUM(F6:F10) -> 462436 | G5: =SUM(G6:G10) -> 412000 | H5: =SUM(H6:H10) -> 424000 | I5: =SUM(I6:I10) -> 402000 | J5: =SUM(J6:J10) -> 452020 | K5: =SUM(K6:K10) -> 456000 | L5: =SUM(L6:L10) -> 402000 | ... BK5: =SUM(BK6:BK10) -> 650000 | BL5: =SUM(E5:O5) -> 4698729 | BM5: - | BN5: =SUM(P5:AA5) -> 7536362 | BO5: =BN5/BL5 -> 1.603915 | BP5: =SUM(AB5:AM5) -> 11000467 | BQ5: =BP5/BN5 -> 1.4596522 | BR5: =SUM(AN5:AY5) -> 9872000 | BS5: =BR5/BP5 -> 0.89741645 | BT5: =SUM(AZ5:BK5) -> 8172000 | BU5: =BT5/BR5 -> 0.82779579
D6: 総支給額(給与) | E6: ='FY-1(月次)収入予実'!F9 -> 353933 | F6: ='FY-1(月次)収入予実'!G9 -> 462436 | G6: ='FY-1(月次)収入予実'!H9 -> 400000 | H6: ='FY-1(月次)収入予実'!I9 -> 422000 | I6: ='FY-1(月次)収入予実'!J9 -> 400000 | J6: ='FY-1(月次)収入予実'!K9 -> 438020 | K6: ='FY-1(月次)収入予実'!L9 -> 454000 | L6: ='FY-1(月次)収入予実'!M9 -> 400000 | ... O6: ='FY-1(月次)収入予実'!P9 -> 400000 | P6: ='FY-2(月次)収入'!D10 -> 438020 | Q6: ='FY-2(月次)収入'!E10 -> 396656 | R6: ='FY-2(月次)収入'!F10 -> 0 | S6: ='FY-2(月次)収入'!G10 -> 544857 | T6: ='FY-2(月次)収入'!H10 -> 588222 | U6: ='FY-2(月次)収入'!I10 -> 687312 | V6: ='FY-2(月次)収入'!J10 -> 648517 | W6: ='FY-2(月次)収入'!K10 -> 668694 | ... AA6: ='FY-2(月次)収入'!O10 -> 563046 | AB6: ='FY-3(月次)収入'!D10 -> 687826 | AC6: ='FY-3(月次)収入'!E10 -> 562185 | AD6: ='FY-3(月次)収入'!F10 -> 562651 | AE6: ='FY-3(月次)収入'!G10 -> 664030 | AF6: ='FY-3(月次)収入'!H10 -> 559179 | AG6: ='FY-3(月次)収入'!I10 -> 671386 | AH6: ='FY-3(月次)収入'!J10 -> 566915 | AI6: ='FY-3(月次)収入'!K10 -> 674646 | ... AM6: ='FY-3(月次)収入'!O10 -> 561030 | AN6: 700000 | AO6: 700000 | AP6: 750000 | AQ6: 750000 | AR6: 750000 | AS6: 750000 | AT6: 750000 | AU6: 750000 | AV6: 750000 | AW6: 750000 | AX6: 750000 | AY6: 750000 | AZ6: 600000 | BA6: 600000 | BB6: 600000 | BC6: 600000 | BD6: 600000 | BE6: 600000 | BF6: 600000 | BG6: 600000 | BH6: 600000 | BI6: 600000 | BJ6: 600000 | BK6: 600000 | BL6: =SUM(E6:O6) -> 4593389 | BM6: - | BN6: =SUM(P6:AA6) -> 6417998 | BO6: =BN6/BL6 -> 1.397225 | BP6: =SUM(AB6:AM6) -> 7408817 | BQ6: =BP6/BN6 -> 1.1543813 | BR6: =SUM(AN6:AY6) -> 8900000 | BS6: =BR6/BP6 -> 1.2012714 | BT6: =SUM(AZ6:BK6) -> 7200000 | BU6: =BT6/BR6 -> 0.80898876
D7: 経費精算 | E7: - | F7: - | G7: - | H7: - | I7: - | J7: - | K7: - | L7: - | M7: - | N7: - | O7: - | P7: - | Q7: - | R7: ='FY-2(月次)収入'!F5 -> 28513 | S7: ='FY-2(月次)収入'!G5 -> 318 | T7: ='FY-2(月次)収入'!H5 -> 17116 | U7: ='FY-2(月次)収入'!I5 -> 0 | V7: ='FY-2(月次)収入'!J5 -> 2392 | W7: ='FY-2(月次)収入'!K5 -> 7764 | X7: ='FY-2(月次)収入'!L5 -> 128190 | Y7: ='FY-2(月次)収入'!M5 -> 24803 | ... AA7: ='FY-2(月次)収入'!O5 -> 4374 | AB7: ='FY-3(月次)収入'!D5 -> 3318 | AC7: ='FY-3(月次)収入'!E5 -> 3977 | AD7: ='FY-3(月次)収入'!F5 -> 3668 | AE7: ='FY-3(月次)収入'!G5 -> 663 | AF7: ='FY-3(月次)収入'!H5 -> 500 | AG7: ='FY-3(月次)収入'!I5 -> 500 | AH7: ='FY-3(月次)収入'!J5 -> 500 | AI7: ='FY-3(月次)収入'!K5 -> 500 | ... AM7: ='FY-3(月次)収入'!O5 -> 500 | AN7: 0 | AO7: 0 | AP7: 0 | AQ7: 0 | AR7: 0 | AS7: 10000 | AT7: 0 | AU7: 0 | AV7: 0 | AW7: 0 | AX7: 0 | AY7: 0 | AZ7: 0 | BA7: 0 | BB7: 0 | BC7: 0 | BD7: 0 | BE7: 10000 | BF7: 0 | BG7: 0 | BH7: 0 | BI7: 0 | BJ7: 0 | BK7: 0 | BL7: =SUM(E7:O7) -> 0 | BM7: - | BN7: =SUM(P7:AA7) -> 218449 | BO7: =BN7/BL7 -> #DIV/0! | BP7: =SUM(AB7:AM7) -> 15626 | BQ7: =BP7/BN7 -> 0.07153157 | BR7: =SUM(AN7:AY7) -> 10000 | BS7: =BR7/BP7 -> 0.63995904 | BT7: =SUM(AZ7:BK7) -> 10000 | BU7: =BT7/BR7 -> 1
D8: 家族収入 | E8: ='FY-1(月次)収入予実'!F7 -> 10000 | F8: ='FY-1(月次)収入予実'!G7 -> 0 | G8: ='FY-1(月次)収入予実'!H7 -> 10000 | H8: ='FY-1(月次)収入予実'!I7 -> 0 | I8: ='FY-1(月次)収入予実'!J7 -> 0 | J8: ='FY-1(月次)収入予実'!K7 -> 10000 | K8: ='FY-1(月次)収入予実'!L7 -> 0 | L8: ='FY-1(月次)収入予実'!M7 -> 0 | ... O8: ='FY-1(月次)収入予実'!P7 -> 0 | P8: ='FY-2(月次)収入'!D6 -> 0 | Q8: ='FY-2(月次)収入'!E6 -> 20000 | R8: ='FY-2(月次)収入'!F6 -> 10000 | S8: ='FY-2(月次)収入'!G6 -> 0 | T8: ='FY-2(月次)収入'!H6 -> 18000 | U8: ='FY-2(月次)収入'!I6 -> 10000 | V8: ='FY-2(月次)収入'!J6 -> 0 | W8: ='FY-2(月次)収入'!K6 -> 0 | ... AA8: ='FY-2(月次)収入'!O6 -> 0 | AB8: ='FY-3(月次)収入'!D6 -> 0 | AC8: ='FY-3(月次)収入'!E6 -> 10000 | AD8: ='FY-3(月次)収入'!F6 -> 0 | AE8: ='FY-3(月次)収入'!G6 -> 0 | AF8: ='FY-3(月次)収入'!H6 -> 0 | AG8: ='FY-3(月次)収入'!I6 -> 0 | AH8: ='FY-3(月次)収入'!J6 -> 0 | AI8: ='FY-3(月次)収入'!K6 -> 0 | ... AM8: ='FY-3(月次)収入'!O6 -> 0 | AN8: 0 | AO8: 0 | AP8: 0 | AQ8: 0 | AR8: 0 | AS8: 0 | AT8: 0 | AU8: 0 | AV8: 50000 | AW8: 0 | AX8: 0 | AY8: 0 | AZ8: 0 | BA8: 0 | BB8: 0 | BC8: 0 | BD8: 0 | BE8: 0 | BF8: 0 | BG8: 0 | BH8: 50000 | BI8: 0 | BJ8: 0 | BL8: =SUM(E8:O8) -> 80000 | BM8: - | BN8: =SUM(P8:AA8) -> 97500 | BO8: =BN8/BL8 -> 1.21875 | BP8: =SUM(AB8:AM8) -> 49500 | BQ8: =BP8/BN8 -> 0.50769231 | BR8: =SUM(AN8:AY8) -> 50000 | BS8: =BR8/BP8 -> 1.010101 | BT8: =SUM(AZ8:BK8) -> 50000 | BU8: =BT8/BR8 -> 1
D9: その他収入 | E9: ='FY-1(月次)収入予実'!F8 -> 0 | F9: ='FY-1(月次)収入予実'!G8 -> 0 | G9: ='FY-1(月次)収入予実'!H8 -> 0 | H9: ='FY-1(月次)収入予実'!I8 -> 0 | I9: ='FY-1(月次)収入予実'!J8 -> 0 | J9: ='FY-1(月次)収入予実'!K8 -> 0 | K9: ='FY-1(月次)収入予実'!L8 -> 0 | L9: ='FY-1(月次)収入予実'!M8 -> 0 | ... O9: ='FY-1(月次)収入予実'!P8 -> 0 | P9: ='FY-2(月次)収入'!D7 -> 11000 | Q9: ='FY-2(月次)収入'!E7 -> 5000 | R9: ='FY-2(月次)収入'!F7 -> 0 | S9: ='FY-2(月次)収入'!G7 -> 42000 | T9: ='FY-2(月次)収入'!H7 -> 981 | U9: ='FY-2(月次)収入'!I7 -> 21382 | V9: ='FY-2(月次)収入'!J7 -> 1323 | W9: ='FY-2(月次)収入'!K7 -> 42292 | ... AA9: ='FY-2(月次)収入'!O7 -> 329075 | AB9: ='FY-3(月次)収入'!D7 -> 30000 | AC9: ='FY-3(月次)収入'!E7 -> 68524 | AD9: ='FY-3(月次)収入'!F7 -> 72440 | AE9: ='FY-3(月次)収入'!G7 -> 28000 | AF9: ='FY-3(月次)収入'!H7 -> 328000 | AG9: ='FY-3(月次)収入'!I7 -> 328000 | AH9: ='FY-3(月次)収入'!J7 -> 328000 | AI9: ='FY-3(月次)収入'!K7 -> 628000 | ... AM9: ='FY-3(月次)収入'!O7 -> 328000 | AN9: 100000 | AO9: 50000 | AP9: 100000 | AQ9: 50000 | AR9: 100000 | AS9: 50000 | AT9: 100000 | AU9: 50000 | AV9: 100000 | AW9: 50000 | AX9: 100000 | AY9: 50000 | AZ9: 100000 | BA9: 50000 | BB9: 100000 | BC9: 50000 | BD9: 100000 | BE9: 50000 | BF9: 100000 | BG9: 50000 | BH9: 100000 | BI9: 50000 | BJ9: 100000 | BK9: 50000 | BL9: =SUM(E9:O9) -> 7540 | BM9: - | BN9: =SUM(P9:AA9) -> 704810 | BO9: =BN9/BL9 -> 93.476127 | BP9: =SUM(AB9:AM9) -> 3422964 | BQ9: =BP9/BN9 -> 4.8565769 | BR9: =SUM(AN9:AY9) -> 900000 | BS9: =BR9/BP9 -> 0.26293002 | BT9: =SUM(AZ9:BK9) -> 900000 | BU9: =BT9/BR9 -> 1
D10: ポイント収入 | E10: ='FY-1(月次)収入予実'!F6 -> 2000 | F10: ='FY-1(月次)収入予実'!G6 -> 0 | G10: ='FY-1(月次)収入予実'!H6 -> 2000 | H10: ='FY-1(月次)収入予実'!I6 -> 2000 | I10: ='FY-1(月次)収入予実'!J6 -> 2000 | J10: ='FY-1(月次)収入予実'!K6 -> 4000 | K10: ='FY-1(月次)収入予実'!L6 -> 2000 | L10: ='FY-1(月次)収入予実'!M6 -> 2000 | ... O10: ='FY-1(月次)収入予実'!P6 -> 0 | P10: ='FY-2(月次)収入'!D8 -> 3985 | Q10: ='FY-2(月次)収入'!E8 -> 3280 | R10: ='FY-2(月次)収入'!F8 -> 30383 | S10: ='FY-2(月次)収入'!G8 -> 3158 | T10: ='FY-2(月次)収入'!H8 -> 2090 | U10: ='FY-2(月次)収入'!I8 -> 7250 | V10: ='FY-2(月次)収入'!J8 -> 6752 | W10: ='FY-2(月次)収入'!K8 -> 3949 | ... AA10: ='FY-2(月次)収入'!O8 -> 10429 | AB10: ='FY-3(月次)収入'!D8 -> 0 | AC10: ='FY-3(月次)収入'!E8 -> 4297 | AD10: ='FY-3(月次)収入'!F8 -> 46735 | AE10: ='FY-3(月次)収入'!G8 -> 3158 | AF10: ='FY-3(月次)収入'!H8 -> 2090 | AG10: ='FY-3(月次)収入'!I8 -> 7250 | AH10: ='FY-3(月次)収入'!J8 -> 6752 | AI10: ='FY-3(月次)収入'!K8 -> 3949 | ... AM10: ='FY-3(月次)収入'!O8 -> 3000 | AN10: 3000 | AO10: 0 | AP10: 0 | AQ10: 3000 | AR10: 0 | AS10: 0 | AT10: 3000 | AU10: 0 | AV10: 0 | AW10: 3000 | AX10: 0 | AY10: 0 | AZ10: 3000 | BA10: 0 | BB10: 0 | BC10: 3000 | BD10: 0 | BE10: 0 | BF10: 3000 | BG10: 0 | BH10: 0 | BI10: 3000 | BJ10: 0 | BK10: 0 | BL10: =SUM(E10:O10) -> 17800 | BM10: - | BN10: =SUM(P10:AA10) -> 97605 | BO10: =BN10/BL10 -> 5.483427 | BP10: =SUM(AB10:AM10) -> 103560 | BQ10: =BP10/BN10 -> 1.0610112 | BR10: =SUM(AN10:AY10) -> 12000 | BS10: =BR10/BP10 -> 0.11587486 | BT10: =SUM(AZ10:BK10) -> 12000 | BU10: =BT10/BR10 -> 1
D11: （合計額に対するポイントの割合） | E11: =E10/E5 -> 0.0054654814 | F11: =F10/F5 -> 0 | G11: =G10/G5 -> 0.0048543689 | H11: =H10/H5 -> 0.0047169811 | I11: =I10/I5 -> 0.0049751244 | J11: =J10/J5 -> 0.008849166 | K11: =K10/K5 -> 0.0043859649 | L11: =L10/L5 -> 0.0049751244 | ... BL11: =BL10/BL5 -> 0.0037882585 | BN11: =BN10/BN5 -> 0.012951209 | BP11: =BP10/BP5 -> 0.0094141458 | BR11: =BR10/BR5 -> 0.0012155592 | BT11: =BT10/BT5 -> 0.0014684288
C12: 控除額内訳 | D12: 合計 | E12: =SUM(E13:E21) -> 61448 | F12: =SUM(F13:F21) -> 53679 | G12: =SUM(G13:G21) -> 72704 | H12: =SUM(H13:H21) -> 85236 | I12: =SUM(I13:I21) -> 83804 | J12: =SUM(J13:J21) -> 90612 | K12: =SUM(K13:K21) -> 95118 | L12: =SUM(L13:L21) -> 69214 | ... BK12: =SUM(BK13:BK21) -> 141470 | BL12: =SUM(E12:P12) -> 978734 | BM12: - | BN12: =SUM(P12:AA12) -> 1343774.3 | BO12: =BN12/BL12 -> 1.3729719 | BP12: =SUM(AB12:AM12) -> 1708908 | BQ12: =BP12/BN12 -> 1.2717225 | BR12: =SUM(AN12:AY12) -> 1588840 | BS12: =BR12/BP12 -> 0.92973993 | BT12: =SUM(AZ12:BK12) -> 1708840 | BU12: =BT12/BR12 -> 1.0755268
D13: 住民税 | E13: ='FY-1(月次)収入予実'!F11 -> 0 | F13: ='FY-1(月次)収入予実'!G11 -> 0 | G13: ='FY-1(月次)収入予実'!H11 -> 19400 | H13: ='FY-1(月次)収入予実'!I11 -> 18400 | I13: ='FY-1(月次)収入予実'!J11 -> 18400 | J13: ='FY-1(月次)収入予実'!K11 -> 18400 | K13: ='FY-1(月次)収入予実'!L11 -> 18400 | L13: ='FY-1(月次)収入予実'!M11 -> 18400 | ... O13: ='FY-1(月次)収入予実'!P11 -> 18400 | P13: ='FY-2(月次)収入'!D13 -> 18400 | Q13: ='FY-2(月次)収入'!E13 -> 18400 | R13: ='FY-2(月次)収入'!F13 -> 0 | S13: ='FY-2(月次)収入'!G13 -> 21100 | T13: ='FY-2(月次)収入'!H13 -> 20200 | U13: ='FY-2(月次)収入'!I13 -> 20200 | V13: ='FY-2(月次)収入'!J13 -> 20200 | W13: ='FY-2(月次)収入'!K13 -> 20200 | ... AA13: ='FY-2(月次)収入'!O13 -> 20200 | AB13: ='FY-3(月次)収入'!D13 -> 20200 | AC13: ='FY-3(月次)収入'!E13 -> 20200 | AD13: ='FY-3(月次)収入'!F13 -> 25100 | AE13: ='FY-3(月次)収入'!G13 -> 25200 | AF13: ='FY-3(月次)収入'!H13 -> 25200 | AG13: ='FY-3(月次)収入'!I13 -> 25200 | AH13: ='FY-3(月次)収入'!J13 -> 25200 | AI13: ='FY-3(月次)収入'!K13 -> 25200 | ... AM13: ='FY-3(月次)収入'!O13 -> 25200 | AN13: 30000 | AO13: 30000 | AP13: 30000 | AQ13: 30000 | AR13: 30000 | AS13: 30000 | AT13: 30000 | AU13: 30000 | AV13: 30000 | AW13: 30000 | AX13: 30000 | AY13: 30000 | AZ13: 40000 | BA13: 40000 | BB13: 40000 | BC13: 40000 | BD13: 40000 | BE13: 40000 | BF13: 40000 | BG13: 40000 | BH13: 40000 | BI13: 40000 | BJ13: 40000 | BK13: 40000 | BL13: =SUM(E13:O13) -> 166600 | BM13: - | BN13: =SUM(P13:AA13) -> 219500 | BO13: =BN13/BL13 -> 1.317527 | BP13: =SUM(AB13:AM13) -> 292300 | BQ13: =BP13/BN13 -> 1.3316629 | BR13: =SUM(AN13:AY13) -> 360000 | BS13: =BR13/BP13 -> 1.2316114 | BT13: =SUM(AZ13:BK13) -> 480000 | BU13: =BT13/BR13 -> 1.3333333
D14: 所得税 | E14: ='FY-1(月次)収入予実'!F12 -> 8420 | F14: ='FY-1(月次)収入予実'!G12 -> 17240 | G14: ='FY-1(月次)収入予実'!H12 -> 12100 | H14: ='FY-1(月次)収入予実'!I12 -> 14060 | I14: ='FY-1(月次)収入予実'!J12 -> 12100 | J14: ='FY-1(月次)収入予実'!K12 -> 11610 | K14: ='FY-1(月次)収入予実'!L12 -> 16020 | L14: ='FY-1(月次)収入予実'!M12 -> 11610 | ... O14: ='FY-1(月次)収入予実'!P12 -> 11610 | P14: ='FY-2(月次)収入'!D14 -> 11610 | Q14: ='FY-2(月次)収入'!E14 -> 8670 | R14: ='FY-2(月次)収入'!F14 -> 0 | S14: ='FY-2(月次)収入'!G14 -> 21070 | T14: ='FY-2(月次)収入'!H14 -> 28420 | U14: ='FY-2(月次)収入'!I14 -> 45440 | V14: ='FY-2(月次)収入'!J14 -> 38280 | W14: ='FY-2(月次)収入'!K14 -> 42140 | ... AA14: ='FY-2(月次)収入'!O14 -> 20840 | AB14: ='FY-3(月次)収入'!D14 -> 42640 | AC14: ='FY-3(月次)収入'!E14 -> 21330 | AD14: ='FY-3(月次)収入'!F14 -> 21330 | AE14: ='FY-3(月次)収入'!G14 -> 42000 | AF14: ='FY-3(月次)収入'!H14 -> 30000 | AG14: ='FY-3(月次)収入'!I14 -> 30000 | AH14: ='FY-3(月次)収入'!J14 -> 30000 | AI14: ='FY-3(月次)収入'!K14 -> 30000 | ... AM14: ='FY-3(月次)収入'!O14 -> 30000 | AN14: 25000 | AO14: 25000 | AP14: 25000 | AQ14: 25000 | AR14: 25000 | AS14: 25000 | AT14: 25000 | AU14: 25000 | AV14: 25000 | AW14: 25000 | AX14: 25000 | AY14: 25000 | AZ14: 25000 | BA14: 25000 | BB14: 25000 | BC14: 25000 | BD14: 25000 | BE14: 25000 | BF14: 25000 | BG14: 25000 | BH14: 25000 | BI14: 25000 | BJ14: 25000 | BK14: 25000 | BL14: =SUM(E14:O14) -> 143130 | BM14: - | BN14: =SUM(P14:AA14) -> 316930 | BO14: =BN14/BL14 -> 2.2142807 | BP14: =SUM(AB14:AM14) -> 367300 | BQ14: =BP14/BN14 -> 1.158931 | BR14: =SUM(AN14:AY14) -> 300000 | BS14: =BR14/BP14 -> 0.81677103 | BT14: =SUM(AZ14:BK14) -> 300000 | BU14: =BT14/BR14 -> 1
D15: 健康保険料 | E15: ='FY-1(月次)収入予実'!F13 -> 17964 | F15: ='FY-1(月次)収入予実'!G13 -> 17964 | G15: ='FY-1(月次)収入予実'!H13 -> 17964 | H15: ='FY-1(月次)収入予実'!I13 -> 17964 | I15: ='FY-1(月次)収入予実'!J13 -> 17964 | J15: ='FY-1(月次)収入予実'!K13 -> 20459 | K15: ='FY-1(月次)収入予実'!L13 -> 20459 | L15: ='FY-1(月次)収入予実'!M13 -> 20459 | ... O15: ='FY-1(月次)収入予実'!P13 -> 20459 | P15: ='FY-2(月次)収入'!D15 -> 20315 | Q15: ='FY-2(月次)収入'!E15 -> 40630 | R15: ='FY-2(月次)収入'!F15 -> 0 | S15: ='FY-2(月次)収入'!G15 -> 23585 | T15: ='FY-2(月次)収入'!H15 -> 23585 | U15: ='FY-2(月次)収入'!I15 -> 23585 | V15: ='FY-2(月次)収入'!J15 -> 23585 | W15: ='FY-2(月次)収入'!K15 -> 23585 | ... AA15: ='FY-2(月次)収入'!O15 -> 30260 | AB15: ='FY-3(月次)収入'!D15 -> 29140 | AC15: ='FY-3(月次)収入'!E15 -> 29140 | AD15: ='FY-3(月次)収入'!F15 -> 29140 | AE15: ='FY-3(月次)収入'!G15 -> 29140 | AF15: ='FY-3(月次)収入'!H15 -> 29140 | AG15: ='FY-3(月次)収入'!I15 -> 29140 | AH15: ='FY-3(月次)収入'!J15 -> 29140 | AI15: ='FY-3(月次)収入'!K15 -> 29140 | ... AM15: ='FY-3(月次)収入'!O15 -> 29140 | AN15: 20315 | AO15: 40630 | AP15: 23585 | AQ15: 23585 | AR15: 23585 | AS15: 24775 | AT15: 24775 | AU15: 24775 | AV15: 24775 | AW15: 24775 | AX15: 24775 | AY15: 24775 | AZ15: 20315 | BA15: 40630 | BB15: 23585 | BC15: 23585 | BD15: 23585 | BE15: 24775 | BF15: 24775 | BG15: 24775 | BH15: 24775 | BI15: 24775 | BJ15: 24775 | BK15: 24775 | BL15: =SUM(E15:O15) -> 212574 | BM15: - | BN15: =SUM(P15:AA15) -> 293235 | BO15: =BN15/BL15 -> 1.379449 | BP15: =SUM(AB15:AM15) -> 349680 | BQ15: =BP15/BN15 -> 1.1924907 | BR15: =SUM(AN15:AY15) -> 305125 | BS15: =BR15/BP15 -> 0.8725835 | BT15: =SUM(AZ15:BK15) -> 305125 | BU15: =BT15/BR15 -> 1
D16: 雇用保険料 | E16: ='FY-1(月次)収入予実'!F14 -> 2124 | F16: ='FY-1(月次)収入予実'!G14 -> 2775 | G16: ='FY-1(月次)収入予実'!H14 -> 2400 | H16: ='FY-1(月次)収入予実'!I14 -> 2532 | I16: ='FY-1(月次)収入予実'!J14 -> 2400 | J16: ='FY-1(月次)収入予実'!K14 -> 2628 | K16: ='FY-1(月次)収入予実'!L14 -> 2724 | L16: ='FY-1(月次)収入予実'!M14 -> 2400 | ... O16: ='FY-1(月次)収入予実'!P14 -> 2400 | P16: ='FY-2(月次)収入'!D16 -> 2409 | Q16: ='FY-2(月次)収入'!E16 -> 2182 | R16: ='FY-2(月次)収入'!F16 -> 0 | S16: ='FY-2(月次)収入'!G16 -> 2997 | T16: ='FY-2(月次)収入'!H16 -> 3235 | U16: ='FY-2(月次)収入'!I16 -> 3780 | V16: ='FY-2(月次)収入'!J16 -> 3567 | W16: ='FY-2(月次)収入'!K16 -> 3677.817 | ... AA16: ='FY-2(月次)収入'!O16 -> 3096.753 | AB16: ='FY-3(月次)収入'!D16 -> 3783.043 | AC16: ='FY-3(月次)収入'!E16 -> 2810.925 | AD16: ='FY-3(月次)収入'!F16 -> 2813.255 | AE16: ='FY-3(月次)収入'!G16 -> 3320.15 | AF16: ='FY-3(月次)収入'!H16 -> 2795.895 | AG16: ='FY-3(月次)収入'!I16 -> 3356.93 | AH16: ='FY-3(月次)収入'!J16 -> 2834.575 | AI16: ='FY-3(月次)収入'!K16 -> 3373.23 | ... AM16: ='FY-3(月次)収入'!O16 -> 2805.15 | AN16: 2409 | AO16: 2182 | AP16: 2997 | AQ16: 2997 | AR16: 3235 | AS16: 3200 | AT16: 3200 | AU16: 3200 | AV16: 3200 | AW16: 3200 | AX16: 3200 | AY16: 3200 | AZ16: 2409 | BA16: 2182 | BB16: 2997 | BC16: 2997 | BD16: 3235 | BE16: 3200 | BF16: 3200 | BG16: 3200 | BH16: 3200 | BI16: 3200 | BJ16: 3200 | BK16: 3200 | BL16: =SUM(E16:O16) -> 27561 | BM16: - | BN16: =SUM(P16:AA16) -> 35299.277 | BO16: =BN16/BL16 -> 1.2807691 | BP16: =SUM(AB16:AM16) -> 37387.998 | BQ16: =BP16/BN16 -> 1.0591718 | BR16: =SUM(AN16:AY16) -> 36220 | BS16: =BR16/BP16 -> 0.96876008 | BT16: =SUM(AZ16:BK16) -> 36220 | BU16: =BT16/BR16 -> 1
D17: 厚生年金保険料 | E17: ='FY-1(月次)収入予実'!F15 -> 32940 | F17: ='FY-1(月次)収入予実'!G15 -> 32940 | G17: ='FY-1(月次)収入予実'!H15 -> 32940 | H17: ='FY-1(月次)収入予実'!I15 -> 32940 | I17: ='FY-1(月次)収入予実'!J15 -> 32940 | J17: ='FY-1(月次)収入予実'!K15 -> 37515 | K17: ='FY-1(月次)収入予実'!L15 -> 37515 | L17: ='FY-1(月次)収入予実'!M15 -> 37515 | ... O17: ='FY-1(月次)収入予実'!P15 -> 37515 | P17: ='FY-2(月次)収入'!D17 -> 37515 | Q17: ='FY-2(月次)収入'!E17 -> 75030 | R17: ='FY-2(月次)収入'!F17 -> 0 | S17: ='FY-2(月次)収入'!G17 -> 48495 | T17: ='FY-2(月次)収入'!H17 -> 48495 | U17: ='FY-2(月次)収入'!I17 -> 48495 | V17: ='FY-2(月次)収入'!J17 -> 48495 | W17: ='FY-2(月次)収入'!K17 -> 48495 | ... AA17: ='FY-2(月次)収入'!O17 -> 59475 | AB17: ='FY-3(月次)収入'!D17 -> 56730 | AC17: ='FY-3(月次)収入'!E17 -> 56730 | AD17: ='FY-3(月次)収入'!F17 -> 56730 | AE17: ='FY-3(月次)収入'!G17 -> 56730 | AF17: ='FY-3(月次)収入'!H17 -> 56730 | AG17: ='FY-3(月次)収入'!I17 -> 56730 | AH17: ='FY-3(月次)収入'!J17 -> 56730 | AI17: ='FY-3(月次)収入'!K17 -> 56730 | ... AM17: ='FY-3(月次)収入'!O17 -> 56730 | AN17: 37515 | AO17: 75030 | AP17: 48495 | AQ17: 48495 | AR17: 48495 | AS17: 48495 | AT17: 48495 | AU17: 48495 | AV17: 48495 | AW17: 48495 | AX17: 48495 | AY17: 48495 | AZ17: 37515 | BA17: 75030 | BB17: 48495 | BC17: 48495 | BD17: 48495 | BE17: 48495 | BF17: 48495 | BG17: 48495 | BH17: 48495 | BI17: 48495 | BJ17: 48495 | BK17: 48495 | BL17: =SUM(E17:O17) -> 389790 | BM17: - | BN17: =SUM(P17:AA17) -> 581940 | BO17: =BN17/BL17 -> 1.4929577 | BP17: =SUM(AB17:AM17) -> 680760 | BQ17: =BP17/BN17 -> 1.1698113 | BR17: =SUM(AN17:AY17) -> 597495 | BS17: =BR17/BP17 -> 0.87768817 | BT17: =SUM(AZ17:BK17) -> 597495 | BU17: =BT17/BR17 -> 1
D18: 定額減税・確定申告還付 | E18: ='FY-1(月次)収入予実'!F16 -> 0 | F18: ='FY-1(月次)収入予実'!G16 -> -17240 | G18: ='FY-1(月次)収入予実'!H16 -> -12100 | H18: ='FY-1(月次)収入予実'!I16 -> -660 | I18: ='FY-1(月次)収入予実'!J16 -> 0 | J18: ='FY-1(月次)収入予実'!K16 -> 0 | K18: ='FY-1(月次)収入予実'!L16 -> 0 | L18: ='FY-1(月次)収入予実'!M16 -> 0 | ... O18: ='FY-1(月次)収入予実'!P16 -> 0 | P18: ='FY-2(月次)収入'!D18 -> 0 | Q18: ='FY-2(月次)収入'!E18 -> 0 | R18: ='FY-2(月次)収入'!F18 -> 0 | S18: ='FY-2(月次)収入'!G18 -> 0 | T18: ='FY-2(月次)収入'!H18 -> 0 | U18: ='FY-2(月次)収入'!I18 -> 0 | V18: ='FY-2(月次)収入'!J18 -> 0 | W18: ='FY-2(月次)収入'!K18 -> 0 | ... AA18: ='FY-2(月次)収入'!O18 -> 0 | AB18: ='FY-3(月次)収入'!D18 -> -6363 | AC18: ='FY-3(月次)収入'!E18 -> 0 | AD18: ='FY-3(月次)収入'!F18 -> 0 | AE18: ='FY-3(月次)収入'!G18 -> 0 | AF18: ='FY-3(月次)収入'!H18 -> 0 | AG18: ='FY-3(月次)収入'!I18 -> 0 | AH18: ='FY-3(月次)収入'!J18 -> 0 | AI18: ='FY-3(月次)収入'!K18 -> 0 | ... AM18: ='FY-3(月次)収入'!O18 -> 0 | AN18: 0 | AO18: 0 | AP18: 0 | AQ18: 0 | AR18: 0 | AS18: 0 | AT18: 0 | AU18: 0 | AV18: 0 | AW18: 0 | AX18: 0 | AY18: 0 | AZ18: 0 | BA18: 0 | BB18: 0 | BC18: 0 | BD18: 0 | BE18: 0 | BF18: 0 | BG18: 0 | BH18: 0 | BI18: 0 | BJ18: 0 | BK18: 0 | BL18: =SUM(E18:O18) -> -30000 | BM18: - | BN18: =SUM(P18:AA18) -> 0 | BO18: =BN18/BL18 -> 0 | BP18: =SUM(AB18:AM18) -> -6363 | BQ18: =BP18/BN18 -> #DIV/0! | BR18: =SUM(AN18:AY18) -> 0 | BS18: =BR18/BP18 -> 0 | BT18: =SUM(AZ18:BK18) -> 0 | BU18: =BT18/BR18 -> #DIV/0!
D19: 年末調整精算額 | E19: ='FY-1(月次)収入予実'!F17 -> 0 | F19: ='FY-1(月次)収入予実'!G17 -> 0 | G19: ='FY-1(月次)収入予実'!H17 -> 0 | H19: ='FY-1(月次)収入予実'!I17 -> 0 | I19: ='FY-1(月次)収入予実'!J17 -> 0 | J19: ='FY-1(月次)収入予実'!K17 -> 0 | K19: ='FY-1(月次)収入予実'!L17 -> 0 | L19: ='FY-1(月次)収入予実'!M17 -> -21170 | ... O19: ='FY-1(月次)収入予実'!P17 -> 0 | P19: ='FY-2(月次)収入'!D19 -> 0 | Q19: ='FY-2(月次)収入'!E19 -> 0 | R19: ='FY-2(月次)収入'!F19 -> 0 | S19: ='FY-2(月次)収入'!G19 -> 0 | T19: ='FY-2(月次)収入'!H19 -> 0 | U19: ='FY-2(月次)収入'!I19 -> 0 | V19: ='FY-2(月次)収入'!J19 -> 0 | W19: ='FY-2(月次)収入'!K19 -> 0 | ... AA19: ='FY-2(月次)収入'!O19 -> 0 | AB19: ='FY-3(月次)収入'!D19 -> 0 | AC19: ='FY-3(月次)収入'!E19 -> 0 | AD19: ='FY-3(月次)収入'!F19 -> 0 | AE19: ='FY-3(月次)収入'!G19 -> 0 | AF19: ='FY-3(月次)収入'!H19 -> 0 | AG19: ='FY-3(月次)収入'!I19 -> 0 | AH19: ='FY-3(月次)収入'!J19 -> 0 | AI19: ='FY-3(月次)収入'!K19 -> 0 | ... AM19: ='FY-3(月次)収入'!O19 -> 0 | AN19: 0 | AO19: 0 | AP19: 0 | AQ19: 0 | AR19: 0 | AS19: 0 | AT19: 0 | AU19: 0 | AV19: -10000 | AW19: 0 | AX19: 0 | AY19: 0 | AZ19: 0 | BA19: 0 | BB19: 0 | BC19: 0 | BD19: 0 | BE19: 0 | BF19: 0 | BG19: 0 | BH19: -10000 | BI19: 0 | BJ19: 0 | BK19: 0 | BL19: =SUM(E19:O19) -> -21170 | BM19: - | BN19: =SUM(P19:AA19) -> -103130 | BO19: =BN19/BL19 -> 4.8715163 | BP19: =SUM(AB19:AM19) -> -20000 | BQ19: =BP19/BN19 -> 0.19392999 | BR19: =SUM(AN19:AY19) -> -10000 | BS19: =BR19/BP19 -> 0.5 | BT19: =SUM(AZ19:BK19) -> -10000 | BU19: =BT19/BR19 -> 1
D20: 子ども・子育て支援金 | E20: 0 | F20: 0 | G20: 0 | H20: 0 | I20: 0 | J20: 0 | K20: 0 | L20: 0 | M20: 0 | N20: 0 | O20: 0 | P20: 0 | Q20: 0 | R20: 0 | S20: 0 | T20: 0 | U20: 0 | V20: 0 | W20: 0 | X20: 0 | Y20: 0 | Z20: 0 | AA20: 0 | AB20: ='FY-3(月次)収入'!D20 -> 0 | AC20: ='FY-3(月次)収入'!E20 -> 713 | AD20: ='FY-3(月次)収入'!F20 -> 713 | AE20: ='FY-3(月次)収入'!G20 -> 713 | AF20: ='FY-3(月次)収入'!H20 -> 713 | AG20: ='FY-3(月次)収入'!I20 -> 713 | AH20: ='FY-3(月次)収入'!J20 -> 713 | AI20: ='FY-3(月次)収入'!K20 -> 713 | ... AM20: ='FY-3(月次)収入'!O20 -> 713 | AN20: 0 | AO20: 0 | AP20: 0 | AQ20: 0 | AR20: 0 | AS20: 0 | AT20: 0 | AU20: 0 | AV20: 0 | AW20: 0 | AX20: 0 | AY20: 0 | AZ20: 0 | BA20: 0 | BB20: 0 | BC20: 0 | BD20: 0 | BE20: 0 | BF20: 0 | BG20: 0 | BH20: 0 | BI20: 0 | BJ20: 0 | BK20: 0 | BL20: =SUM(E20:O20) -> 0 | BM20: - | BN20: =SUM(P20:AA20) -> 0 | BO20: =BN20/BL20 -> #DIV/0! | BP20: =SUM(AB20:AM20) -> 7843 | BQ20: =BP20/BN20 -> #DIV/0! | BR20: =SUM(AN20:AY20) -> 0 | BS20: =BR20/BP20 -> 0 | BT20: =SUM(AZ20:BK20) -> 0 | BU20: =BT20/BR20 -> #DIV/0!
D21: ふるさと納税返金額 | E21: ='FY-1(月次)収入予実'!F18 -> 0 | F21: ='FY-1(月次)収入予実'!G18 -> 0 | G21: ='FY-1(月次)収入予実'!H18 -> 0 | H21: ='FY-1(月次)収入予実'!I18 -> 0 | I21: ='FY-1(月次)収入予実'!J18 -> 0 | J21: ='FY-1(月次)収入予実'!K18 -> 0 | K21: ='FY-1(月次)収入予実'!L18 -> 0 | L21: ='FY-1(月次)収入予実'!M18 -> 0 | ... O21: ='FY-1(月次)収入予実'!P18 -> 0 | P21: ='FY-2(月次)収入'!D20 -> 0 | Q21: ='FY-2(月次)収入'!E20 -> 0 | R21: ='FY-2(月次)収入'!F20 -> 0 | S21: ='FY-2(月次)収入'!G20 -> 0 | T21: ='FY-2(月次)収入'!H20 -> 0 | U21: ='FY-2(月次)収入'!I20 -> 0 | V21: ='FY-2(月次)収入'!J20 -> 0 | W21: ='FY-2(月次)収入'!K20 -> 0 | ... AA21: ='FY-2(月次)収入'!O20 -> 0 | AB21: ='FY-3(月次)収入'!D21 -> 0 | AC21: ='FY-3(月次)収入'!E21 -> 0 | AD21: ='FY-3(月次)収入'!F21 -> 0 | AE21: ='FY-3(月次)収入'!G21 -> 0 | AF21: ='FY-3(月次)収入'!H21 -> 0 | AG21: ='FY-3(月次)収入'!I21 -> 0 | AH21: ='FY-3(月次)収入'!J21 -> 0 | AI21: ='FY-3(月次)収入'!K21 -> 0 | ... AM21: ='FY-3(月次)収入'!O21 -> 0 | AN21: 0 | AO21: 0 | AP21: 0 | AQ21: 0 | AR21: 0 | AS21: 0 | AT21: 0 | AU21: 0 | AV21: 0 | AW21: 0 | AX21: 0 | AY21: 0 | AZ21: 0 | BA21: 0 | BB21: 0 | BC21: 0 | BD21: 0 | BE21: 0 | BF21: 0 | BG21: 0 | BH21: 0 | BI21: 0 | BJ21: 0 | BK21: 0 | BL21: =SUM(E21:O21) -> 0 | BM21: - | BN21: =SUM(P21:AA21) -> 0 | BO21: =BN21/BL21 -> #DIV/0! | BP21: =SUM(AB21:AM21) -> 0 | BQ21: =BP21/BN21 -> #DIV/0! | BR21: =SUM(AN21:AY21) -> 0 | BS21: =BR21/BP21 -> #DIV/0! | BT21: =SUM(AZ21:BK21) -> 0 | BU21: =BT21/BR21 -> #DIV/0!
D22: （総支給額に対する控除額の割合） | E22: =E12/E6 -> 0.17361478 | F22: =F12/F6 -> 0.11607877 | G22: =G12/G6 -> 0.18176 | H22: =H12/H6 -> 0.20198104 | I22: =I12/I6 -> 0.20951 | J22: =J12/J6 -> 0.20686727 | K22: =K12/K6 -> 0.20951101 | L22: =L12/L6 -> 0.173035 | ... BL22: =BL12/BL6 -> 0.21307449 | BM22: - | BN22: =IFERROR((BN12-BN9)/(BN5-BN9),"0%") -> 0.093531349 | BO22: =BN22-BL22 -> -0.11954314 | BP22: =IFERROR((BP12-BP9)/(BP5-BP9),"0%") -> -0.22620328 | BQ22: =BP22-BN22 -> -0.31973463 | BR22: =IFERROR((BR12-BR9)/(BR5-BR9),"0%") -> 0.076776638 | BS22: =BR22-BP22 -> 0.30297991 | BT22: =IFERROR((BT12-BT9)/(BT5-BT9),"0%") -> 0.11122662 | BU22: =BT22-BR22 -> 0.034449984
C23: 可処分所得 | D23: 合計 | E23: =E5-E12 -> 304485 | F23: =F5-F12 -> 408757 | G23: =G5-G12 -> 339296 | H23: =H5-H12 -> 338764 | I23: =I5-I12 -> 318196 | J23: =J5-J12 -> 361408 | K23: =K5-K12 -> 360882 | L23: =L5-L12 -> 332786 | ... BL23: =BL5-BL12 -> 3719995 | BM23: - | BN23: =BN5-BN12 -> 6192587.7 | BO23: =BN23/BL23 -> 1.6646764 | BP23: =BP5-BP12 -> 9291559 | BQ23: =BP23/BN23 -> 1.5004324 | BR23: =BR5-BR12 -> 8283160 | BS23: =BR23/BP23 -> 0.8914715 | BT23: =BT5-BT12 -> 6463160 | BU23: =BT23/BR23 -> 0.78027709
D24: 収入合計－控除額合計 | E24: =E5-E12 -> 304485 | F24: =F5-F12 -> 408757 | G24: =G5-G12 -> 339296 | H24: =H5-H12 -> 338764 | I24: =I5-I12 -> 318196 | J24: =J5-J12 -> 361408 | K24: =K5-K12 -> 360882 | L24: =L5-L12 -> 332786 | ... BL24: =BL5-BL12 -> 3719995 | BM24: - | BN24: =BN5-BN12 -> 6192587.7 | BO24: =BN24-BL24 -> 2472592.7 | BP24: =BP5-BP12 -> 9291559 | BQ24: =BP24-BN24 -> 3098971.3 | BR24: =BR5-BR12 -> 8283160 | BS24: =BR24-BP24 -> -1008399 | BT24: =BT5-BT12 -> 6463160 | BU24: =BT24-BR24 -> -1820000
D25: （収入合計に対する可処分所得の割合） | E25: =E23/E5 -> 0.83207855 | F25: =F23/F5 -> 0.88392123 | G25: =G23/G5 -> 0.82353398 | H25: =H23/H5 -> 0.7989717 | I25: =I23/I5 -> 0.79153234 | J25: =J23/J5 -> 0.79953984 | K25: =K23/K5 -> 0.79140789 | L25: =L23/L5 -> 0.82782587 | ... BL25: =BL23/BL5 -> 0.79170239 | BM25: - | BN25: =BN23/BN5 -> 0.82169457 | BO25: =BN25-BL25 -> 0.029992174 | BP25: =BP23/BP5 -> 0.84465132 | BQ25: =BP25-BN25 -> 0.022956754 | BR25: =BR23/BR5 -> 0.83905592 | BS25: =BR25-BP25 -> -0.005595407 | BT25: =BT23/BT5 -> 0.79089085 | BU25: =BT25-BR25 -> -0.048165069
C27: 支出管理 | E27: FY-1（2024年5月～2025年3月） | P27: FY-2（2025年4月～2026年3月） | AB27: FY-3（2026年4月～2027年3月） | AN27: FY-4（2027年4月～2028年3月） | AZ27: FY-5（2028年4月～2029年3月） | BL27: FY-1 | BN27: FY-2 | BP27: FY-3 | BR27: FY-4 | BT27: FY-5
C28: 氏名 | D28: 雇用形態 | E28: 5月 | F28: 6月 | G28: 7月 | H28: 8月 | I28: 9月 | J28: 10月 | K28: 11月 | L28: 12月 | M28: 1月 | N28: 2月 | O28: 3月 | P28: 4月 | Q28: 5月 | R28: 6月 | S28: 7月 | T28: 8月 | U28: 9月 | V28: 10月 | W28: 11月 | X28: 12月 | Y28: 1月 | Z28: 2月 | AA28: 3月 | AB28: 4月 | AC28: 5月 | AD28: 6月 | AE28: 7月 | AF28: 8月 | AG28: 9月 | AH28: 10月 | AI28: 11月 | AJ28: 12月 | AK28: 1月 | AL28: 2月 | AM28: 3月 | AN28: 4月 | AO28: 5月 | AP28: 6月 | AQ28: 7月 | AR28: 8月 | AS28: 9月 | AT28: 10月 | AU28: 11月 | AV28: 12月 | AW28: 1月 | AX28: 2月 | AY28: 3月 | AZ28: 4月 | BA28: 5月 | BB28: 6月 | BC28: 7月 | BD28: 8月 | BE28: 9月 | BF28: 10月 | BG28: 11月 | BH28: 12月 | BI28: 1月 | BJ28: 2月 | BK28: 3月 | BL28: 通期 | BM28: (昨対比) | BN28: 通期 | BO28: (昨対比) | BP28: 通期 | BQ28: (昨対比) | BR28: 通期 | BS28: (昨対比) | BT28: 通期 | BU28: (昨対比)
C29: 固定費・サブスク | D29: 合計 | E29: =SUM(E30:E46) -> 118303 | F29: =SUM(F30:F46) -> 119837 | G29: =SUM(G30:G46) -> 119841 | H29: =SUM(H30:H46) -> 119187 | I29: =SUM(I30:I46) -> 118877 | J29: =SUM(J30:J46) -> 121239 | K29: =SUM(K30:K46) -> 121417 | L29: =SUM(L30:L46) -> 123063 | ... BK29: =SUM(BK30:BK46) -> 174834 | BL29: =SUM(E29:O29) -> 1332533 | BM29: - | BN29: =SUM(P29:AA29) -> 1935350 | BO29: =BN29/BL29 -> 1.4523843 | BP29: =SUM(AB29:AM29) -> 1899955 | BQ29: =BP29/BN29 -> 0.98171132 | BR29: =SUM(AN29:AY29) -> 2098008 | BS29: =BR29/BP29 -> 1.1042409 | BT29: =SUM(AZ29:BK29) -> 2098008 | BU29: =BT29/BR29 -> 1
D30: 家賃※水道光熱費込み | E30: ='FY-1(月次)支出予実'!C8 -> 60682 | F30: ='FY-1(月次)支出予実'!D8 -> 62216 | G30: ='FY-1(月次)支出予実'!E8 -> 62216 | H30: ='FY-1(月次)支出予実'!F8 -> 62216 | I30: ='FY-1(月次)支出予実'!G8 -> 62216 | J30: ='FY-1(月次)支出予実'!H8 -> 62216 | K30: ='FY-1(月次)支出予実'!I8 -> 62216 | L30: ='FY-1(月次)支出予実'!J8 -> 65516 | ... O30: ='FY-1(月次)支出予実'!M8 -> 62216 | P30: ='FY-2(月次)支出'!D7 -> 59149 | Q30: ='FY-2(月次)支出'!E7 -> 88700 | R30: ='FY-2(月次)支出'!F7 -> 89587 | S30: ='FY-2(月次)支出'!G7 -> 89587 | T30: ='FY-2(月次)支出'!H7 -> 89587 | U30: ='FY-2(月次)支出'!I7 -> 89587 | V30: ='FY-2(月次)支出'!J7 -> 89587 | W30: ='FY-2(月次)支出'!K7 -> 129987 | ... AA30: ='FY-2(月次)支出'!O7 -> 129987 | AB30: ='FY-3(月次)支出 '!D7 -> 129987 | AC30: ='FY-3(月次)支出 '!E7 -> 129987 | AD30: ='FY-3(月次)支出 '!F7 -> 129987 | AE30: ='FY-3(月次)支出 '!G7 -> 129987 | AF30: ='FY-3(月次)支出 '!H7 -> 129987 | AG30: ='FY-3(月次)支出 '!I7 -> 129987 | AH30: ='FY-3(月次)支出 '!J7 -> 129987 | AI30: ='FY-3(月次)支出 '!K7 -> 129987 | ... AM30: ='FY-3(月次)支出 '!O7 -> 129987 | AN30: 129987 | AO30: 129987 | AP30: 129987 | AQ30: 129987 | AR30: 129987 | AS30: 129987 | AT30: 129987 | AU30: 129987 | AV30: 129987 | AW30: 129987 | AX30: 129987 | AY30: 129987 | AZ30: 129987 | BA30: 129987 | BB30: 129987 | BC30: 129987 | BD30: 129987 | BE30: 129987 | BF30: 129987 | BG30: 129987 | BH30: 129987 | BI30: 129987 | BJ30: 129987 | BK30: 129987 | BL30: =SUM(E30:O30) -> 686142 | BM30: - | BN30: =SUM(P30:AA30) -> 1245687 | BO30: =BN30/BL30 -> 1.8154945 | BP30: =SUM(AB30:AM30) -> 1559812 | BQ30: =BP30/BN30 -> 1.2521701 | BR30: =SUM(AN30:AY30) -> 1559844 | BS30: =BR30/BP30 -> 1.0000205 | BT30: =SUM(AZ30:BK30) -> 1559844 | BU30: =BT30/BR30 -> 1
D31: 生命保険料 | E31: ='FY-1(月次)支出予実'!C6 -> 9307 | F31: ='FY-1(月次)支出予実'!D6 -> 9307 | G31: ='FY-1(月次)支出予実'!E6 -> 9307 | H31: ='FY-1(月次)支出予実'!F6 -> 9307 | I31: ='FY-1(月次)支出予実'!G6 -> 9307 | J31: ='FY-1(月次)支出予実'!H6 -> 9307 | K31: ='FY-1(月次)支出予実'!I6 -> 9307 | L31: ='FY-1(月次)支出予実'!J6 -> 9307 | ... O31: ='FY-1(月次)支出予実'!M6 -> 9307 | P31: ='FY-2(月次)支出'!D9 -> 9307 | Q31: ='FY-2(月次)支出'!E9 -> 9307 | R31: ='FY-2(月次)支出'!F9 -> 9307 | S31: ='FY-2(月次)支出'!G9 -> 9307 | T31: ='FY-2(月次)支出'!H9 -> 9307 | U31: ='FY-2(月次)支出'!I9 -> 9307 | V31: ='FY-2(月次)支出'!J9 -> 9307 | W31: ='FY-2(月次)支出'!K9 -> 9307 | ... AA31: ='FY-2(月次)支出'!O9 -> 9307 | AB31: ='FY-3(月次)支出 '!D9 -> 9307 | AC31: ='FY-3(月次)支出 '!E9 -> 0 | AD31: ='FY-3(月次)支出 '!F9 -> 0 | AE31: ='FY-3(月次)支出 '!G9 -> 0 | AF31: ='FY-3(月次)支出 '!H9 -> 0 | AG31: ='FY-3(月次)支出 '!I9 -> 0 | AH31: ='FY-3(月次)支出 '!J9 -> 0 | AI31: ='FY-3(月次)支出 '!K9 -> 0 | ... AM31: ='FY-3(月次)支出 '!O9 -> 0 | AN31: 9307 | AO31: 9307 | AP31: 9307 | AQ31: 9307 | AR31: 9307 | AS31: 9307 | AT31: 9307 | AU31: 9307 | AV31: 9307 | AW31: 9307 | AX31: 9307 | AY31: 9307 | AZ31: 9307 | BA31: 9307 | BB31: 9307 | BC31: 9307 | BD31: 9307 | BE31: 9307 | BF31: 9307 | BG31: 9307 | BH31: 9307 | BI31: 9307 | BJ31: 9307 | BK31: 9307 | BL31: =SUM(E31:O31) -> 102377 | BM31: - | BN31: =SUM(P31:AA31) -> 111684 | BO31: =BN31/BL31 -> 1.0909091 | BP31: =SUM(AB31:AM31) -> 9307 | BQ31: =BP31/BN31 -> 0.083333333 | BR31: =SUM(AN31:AY31) -> 111684 | BS31: =BR31/BP31 -> 12 | BT31: =SUM(AZ31:BK31) -> 111684 | BU31: =BT31/BR31 -> 1
